Workbook

Sheet Hoja1
B2: Zona | C2: Z base(ohm) | D2: V base(kV) | E2: Sbase(MVA) | F2: I base(A)
B3: 1 | C3: =(D3*D3)/E3 -> 10.89 | D3: 33 | E3: 100 | F3: =(E3)/(SQRT(3)*D3) -> 1.7495463
B4: 2 | C4: =(D4*D4)/E3 -> 174.24 | D4: 132 | F4: =(E3)/(SQRT(3)*D4) -> 0.43738657
B5: 3 | D5: 11 | F5: =(E3)/(SQRT(3)*D5) -> 5.2486388
B6: 4 | D6: 1 | F6: =(E3)/(SQRT(3)*D6) -> 57.735027

Sheet Nodos
B1: Barras
B3: Bus | C3: Tipo de bus | D3: Type | E3: Pd | F3: Qd | G3: Gs | H3: Bs | I3: area | J3: Vm | K3: Va | L3: Base kV. | M3: Zona | N3: Vmax | O3: Vmin | Q3: PD | R3: QD | S3: PDEF | T3: QDEF
B4: 1 | C4: Slack | D4: 3 | E4: 0 | F4: 0 | G4: 0 | H4: 0 | I4: 1 | J4: 1.06 | K4: 0 | L4: 132 | M4: 1 | N4: 1.06 | O4: 0.94; | Q4: =E4 -> 0 | R4: =F4 -> 0 | S4: 0 | T4: 0
B5: 2 | C5: PV | D5: 2 | E5: 21.7 | F5: 12.7 | G5: 0 | H5: 0 | I5: 1 | J5: 1043 | K5: -5.48 | L5: 132 | M5: 1 | N5: 1.06 | O5: 0.94; | Q5: =E5 -> 21.7 | R5: =F5 -> 12.7 | S5: 18.3 | T5: =50-12.7 -> 37.3
B6: 3 | C6: PQ | D6: 1 | E6: 2.4 | F6: 1.2 | G6: 0 | H6: 0 | I6: 1 | J6: 1021 | K6: -7.96 | L6: 132 | M6: 1 | N6: 1.06 | O6: 0.94; | Q6: =E6 -> 2.4 | R6: =F6 -> 1.2 | S6: -2.4 | T6: -1.2
B7: 4 | C7: PQ | D7: 1 | E7: 7.6 | F7: 1.6 | G7: 0 | H7: 0 | I7: 1 | J7: 1012 | K7: -9.62 | L7: 132 | M7: 1 | N7: 1.06 | O7: 0.94; | Q7: =E7 -> 7.6 | R7: =F7 -> 1.6 | S7: -7.6 | T7: -1.2
B8: 5 | C8: PV | D8: 2 | E8: 94.2 | F8: 19 | G8: 0 | H8: 0 | I8: 1 | J8: 1.01 | K8: -14.37 | L8: 132 | M8: 1 | N8: 1.06 | O8: 0.94; | Q8: =E8 -> 94.2 | R8: =F8 -> 19 | S8: -94.2 | T8: 0
B9: 6 | C9: PQ | D9: 1 | E9: 0 | F9: 0 | G9: 0 | H9: 0 | I9: 1 | J9: 1.01 | K9: -11.34 | L9: 132 | M9: 1 | N9: 1.06 | O9: 0.94; | Q9: =E9 -> 0 | R9: =F9 -> 0 | S9: =E9 -> 0 | T9: =F9 -> 0
B10: 7 | C10: PQ | D10: 1 | E10: 22.8 | F10: 10.9 | G10: 0 | H10: 0 | I10: 1 | J10: 1002 | K10: -13.12 | L10: 132 | M10: 1 | N10: 1.06 | O10: 0.94; | Q10: =E10 -> 22.8 | R10: =F10 -> 10.9 | S10: 22.8 | T10: -10.9
B11: 8 | C11: PV | D11: 2 | E11: 30 | F11: 30 | G11: 0 | H11: 0 | I11: 1 | J11: 1.01 | K11: -12.1 | L11: 132 | M11: 1 | N11: 1.06 | O11: 0.94; | Q11: =E11 -> 30 | R11: =F11 -> 30 | S11: -30
B12: 9 | C12: PQ | D12: 1 | E12: 0 | F12: 0 | G12: 0 | H12: 0 | I12: 1 | J12: 1051 | K12: -14.38 | L12: 1 | M12: 1 | N12: 1.06 | O12: 0.94; | Q12: =E12 -> 0 | R12: =F12 -> 0 | S12: =E12 -> 0 | T12: =F12 -> 0
B13: 10 | C13: PQ | D13: 1 | E13: 5.8 | F13: 2 | G13: 0 | H13: 19 | I13: 1 | J13: 1045 | K13: -15.97 | L13: 33 | M13: 1 | N13: 1.06 | O13: 0.94; | Q13: =E13 -> 5.8 | R13: =F13 -> 2 | S13: =E13 -> 5.8 | T13: -2
B14: 11 | C14: PV | D14: 2 | E14: 0 | F14: 0 | G14: 0 | H14: 0 | I14: 1 | J14: 1082 | K14: -14.39 | L14: 11 | M14: 1 | N14: 1.06 | O14: 0.94; | Q14: =E14 -> 0 | R14: =F14 -> 0 | S14: =E14 -> 0 | T14: 0
B15: 12 | C15: PQ | D15: 1 | E15: 11.2 | F15: 7.5 | G15: 0 | H15: 0 | I15: 1 | J15: 1057 | K15: -15.24 | L15: 33 | M15: 1 | N15: 1.06 | O15: 0.94; | Q15: =E15 -> 11.2 | R15: =F15 -> 7.5 | S15: =E15 -> 11.2 | T15: -7.5
B16: 13 | C16: PV | D16: 2 | E16: 0 | F16: 0 | G16: 0 | H16: 0 | I16: 1 | J16: 1071 | K16: -15.24 | L16: 11 | M16: 1 | N16: 1.06 | O16: 0.94; | Q16: =E16 -> 0 | R16: =F16 -> 0 | S16: =E16 -> 0 | T16: 0
B17: 14 | C17: PQ | D17: 1 | E17: 6.2 | F17: 1.6 | G17: 0 | H17: 0 | I17: 1 | J17: 1042 | K17: -16.13 | L17: 33 | M17: 1 | N17: 1.06 | O17: 0.94; | Q17: =E17 -> 6.2 | R17: =F17 -> 1.6 | S17: =E17 -> 6.2 | T17: -1.6
B18: 15 | C18: PQ | D18: 1 | E18: 8.2 | F18: 2.5 | G18: 0 | H18: 0 | I18: 1 | J18: 1038 | K18: -16.22 | L18: 33 | M18: 1 | N18: 1.06 | O18: 0.94; | Q18: =E18 -> 8.2 | R18: =F18 -> 2.5 | S18: =E18 -> 8.2 | T18: -2.5
B19: 16 | C19: PQ | D19: 1 | E19: 3.5 | F19: 1.8 | G19: 0 | H19: 0 | I19: 1 | J19: 1045 | K19: -15.83 | L19: 33 | M19: 1 | N19: 1.06 | O19: 0.94; | Q19: =E19 -> 3.5 | R19: =F19 -> 1.8 | S19: =E19 -> 3.5 | T19: -1.8
B20: 17 | C20: PQ | D20: 1 | E20: 9 | F20: 5.8 | G20: 0 | H20: 0 | I20: 1 | J20: 1.04 | K20: -16.14 | L20: 33 | M20: 1 | N20: 1.06 | O20: 0.94; | Q20: =E20 -> 9 | R20: =F20 -> 5.8 | S20: =E20 -> 9 | T20: -5.8
B21: 18 | C21: PQ | D21: 1 | E21: 3.2 | F21: 0.9 | G21: 0 | H21: 0 | I21: 1 | J21: 1028 | K21: -16.82 | L21: 33 | M21: 1 | N21: 1.06 | O21: 0.94; | Q21: =E21 -> 3.2 | R21: =F21 -> 0.9 | S21: =E21 -> 3.2 | T21: -0.9
B22: 19 | C22: PQ | D22: 1 | E22: 9.5 | F22: 3.4 | G22: 0 | H22: 0 | I22: 1 | J22: 1026 | K22: -17 | L22: 33 | M22: 1 | N22: 1.06 | O22: 0.94; | Q22: =E22 -> 9.5 | R22: =F22 -> 3.4 | S22: =E22 -> 9.5 | T22: -3.4
B23: 20 | C23: PQ | D23: 1 | E23: 2.2 | F23: 0.7 | G23: 0 | H23: 0 | I23: 1 | J23: 1.03 | K23: -16.8 | L23: 33 | M23: 1 | N23: 1.06 | O23: 0.94; | Q23: =E23 -> 2.2 | R23: =F23 -> 0.7 | S23: =E23 -> 2.2 | T23: -0.7
B24: 21 | C24: PQ | D24: 1 | E24: 17.5 | F24: 11.2 | G24: 0 | H24: 0 | I24: 1 | J24: 1033 | K24: -16.42 | L24: 33 | M24: 1 | N24: 1.06 | O24: 0.94; | Q24: =E24 -> 17.5 | R24: =F24 -> 11.2 | S24: =E24 -> 17.5 | T24: -11.2
B25: 22 | C25: PQ | D25: 1 | E25: 0 | F25: 0 | G25: 0 | H25: 0 | I25: 1 | J25: 1033 | K25: -16.41 | L25: 33 | M25: 1 | N25: 1.06 | O25: 0.94; | Q25: =E25 -> 0 | R25: =F25 -> 0 | S25: =E25 -> 0 | T25: =F25 -> 0
B26: 23 | C26: PQ | D26: 1 | E26: 3.2 | F26: 1.6 | G26: 0 | H26: 0 | I26: 1 | J26: 1027 | K26: -16.61 | L26: 33 | M26: 1 | N26: 1.06 | O26: 0.94; | Q26: =E26 -> 3.2 | R26: =F26 -> 1.6 | S26: =E26 -> 3.2 | T26: =F26 -> 1.6
B27: 24 | C27: PQ | D27: 1 | E27: 8.7 | F27: 6.7 | G27: 0 | H27: 4.3 | I27: 1 | J27: 1021 | K27: -16.78 | L27: 33 | M27: 1 | N27: 1.06 | O27: 0.94; | Q27: =E27 -> 8.7 | R27: =F27 -> 6.7 | S27: =E27 -> 8.7 | T27: =F27 -> 6.7
B28: 25 | C28: PQ | D28: 1 | E28: 0 | F28: 0 | G28: 0 | H28: 0 | I28: 1 | J28: 1017 | K28: -16.35 | L28: 33 | M28: 1 | N28: 1.06 | O28: 0.94; | Q28: =E28 -> 0 | R28: =F28 -> 0 | S28: =E28 -> 0 | T28: =F28 -> 0
B29: 26 | C29: PQ | D29: 1 | E29: 3.5 | F29: 2.3 | G29: 0 | H29: 0 | I29: 1 | J29: 1 | K29: -16.77 | L29: 33 | M29: 1 | N29: 1.06 | O29: 0.94; | Q29: =E29 -> 3.5 | R29: =F29 -> 2.3 | S29: =E29 -> 3.5 | T29: =F29 -> 2.3
B30: 27 | C30: PQ | D30: 1 | E30: 0 | F30: 0 | G30: 0 | H30: 0 | I30: 1 | J30: 1023 | K30: -15.82 | L30: 33 | M30: 1 | N30: 1.06 | O30: 0.94; | Q30: =E30 -> 0 | R30: =F30 -> 0 | S30: =E30 -> 0 | T30: =F30 -> 0
B31: 28 | C31: PQ | D31: 1 | E31: 0 | F31: 0 | G31: 0 | H31: 0 | I31: 1 | J31: 1007 | K31: -11.97 | L31: 132 | M31: 1 | N31: 1.06 | O31: 0.94; | Q31: =E31 -> 0 | R31: =F31 -> 0 | S31: =E31 -> 0 | T31: =F31 -> 0
B32: 29 | C32: PQ | D32: 1 | E32: 2.4 | F32: 0.9 | G32: 0 | H32: 0 | I32: 1 | J32: 1003 | K32: -17.06 | L32: 33 | M32: 1 | N32: 1.06 | O32: 0.94; | Q32: =E32 -> 2.4 | R32: =F32 -> 0.9 | S32: =E32 -> 2.4 | T32: =F32 -> 0.9
B33: 30 | C33: PQ | D33: 1 | E33: 10.6 | F33: 1.9 | G33: 0 | H33: 0 | I33: 1 | J33: 0.992 | K33: -17.94 | L33: 33 | M33: 1 | N33: 1.06 | O33: 0.94; | Q33: =E33 -> 10.6 | R33: =F33 -> 1.9 | S33: =E33 -> 10.6 | T33: =F33 -> 1.9

Sheet LT
B1: Lineas de transmision
B2: fbus | C2: tbus | D2: r | E2: x | F2: b | G2: rateA | H2: rateB | I2: rateC | J2: ratio | K2: angle | L2: status | M2: angmin | N2: angmax | O2: R | P2: X | Q2: B | R2: B/2 | S2: Complejo(R+jX) | T2: 1/complejo | U2: j B/2
A3: 0 | B3: 1 | C3: 2 | D3: 0.0192 | E3: 0.0575 | F3: 0.0528 | G3: 0 | H3: 0 | I3: 0 | J3: 0 | K3: 0 | L3: 1 | M3: -360 | N3: 360; | O3: =SUBSTITUTE(D3,".",",") -> 0,0192 | P3: =SUBSTITUTE(E3,".",",") -> 0,0575 | Q3: =SUBSTITUTE(F3,".",",") -> 0,0528 | R3: =Q3/2 -> 0.0264 | S3: =COMPLEX(O3,P3) -> 0,0192+0,0575i | T3: =IMDIV(1,S3) -> 5,22464617988566-15,6467268408034i | U3: =COMPLEX(A3,R3) -> 0,0264i
A4: 0 | B4: 1 | C4: 3 | D4: 0.0452 | E4: 0.1652 | F4: 0.0408 | G4: 0 | H4: 0 | I4: 0 | J4: 0 | K4: 0 | L4: 1 | M4: -360 | N4: 360; | O4: =SUBSTITUTE(D4,".",",") -> 0,0452 | P4: =SUBSTITUTE(E4,".",",") -> 0,1652 | Q4: =SUBSTITUTE(F4,".",",") -> 0,0408 | R4: =Q4/2 -> 0.0204 | S4: =COMPLEX(O4,P4) -> 0,0452+0,1652i | T4: =IMDIV(1,S4) -> 1,54086986876698-5,63167483009523i | U4: =COMPLEX(A4,R4) -> 0,0204i
A5: 0 | B5: 2 | C5: 4 | D5: 0.057 | E5: 0.1737 | F5: 0.0368 | G5: 0 | H5: 0 | I5: 0 | J5: 0 | K5: 0 | L5: 1 | M5: -360 | N5: 360; | O5: =SUBSTITUTE(D5,".",",") -> 0,057 | P5: =SUBSTITUTE(E5,".",",") -> 0,1737 | Q5: =SUBSTITUTE(F5,".",",") -> 0,0368 | R5: =Q5/2 -> 0.0184 | S5: =COMPLEX(O5,P5) -> 0,057+0,1737i | T5: =IMDIV(1,S5) -> 1,70553031669903-5,19737922825651i | U5: =COMPLEX(A5,R5) -> 0,0184i
A6: 0 | B6: 3 | C6: 4 | D6: 0.0132 | E6: 0.0379 | F6: 0.0084 | G6: 0 | H6: 0 | I6: 0 | J6: 0 | K6: 0 | L6: 1 | M6: -360 | N6: 360; | O6: =SUBSTITUTE(D6,".",",") -> 0,0132 | P6: =SUBSTITUTE(E6,".",",") -> 0,0379 | Q6: =SUBSTITUTE(F6,".",",") -> 0,0084 | R6: =Q6/2 -> 0.0042 | S6: =COMPLEX(O6,P6) -> 0,0132+0,0379i | T6: =IMDIV(1,S6) -> 8,19544904231211-23,5308726290628i | U6: =COMPLEX(A6,R6) -> 0,0042i
A7: 0 | B7: 2 | C7: 5 | D7: 0.0472 | E7: 0.1983 | F7: 0.0418 | G7: 0 | H7: 0 | I7: 0 | J7: 0 | K7: 0 | L7: 1 | M7: -360 | N7: 360; | O7: =SUBSTITUTE(D7,".",",") -> 0,0472 | P7: =SUBSTITUTE(E7,".",",") -> 0,1983 | Q7: =SUBSTITUTE(F7,".",",") -> 0,0418 | R7: =Q7/2 -> 0.0209 | S7: =COMPLEX(O7,P7) -> 0,0472+0,1983i | T7: =IMDIV(1,S7) -> 1,13596078817388-4,77247932828136i | U7: =COMPLEX(A7,R7) -> 0,0209i
A8: 0 | B8: 2 | C8: 6 | D8: 0.0581 | E8: 0.1763 | F8: 0.0374 | G8: 0 | H8: 0 | I8: 0 | J8: 0 | K8: 0 | L8: 1 | M8: -360 | N8: 360; | O8: =SUBSTITUTE(D8,".",",") -> 0,0581 | P8: =SUBSTITUTE(E8,".",",") -> 0,1763 | Q8: =SUBSTITUTE(F8,".",",") -> 0,0374 | R8: =Q8/2 -> 0.0187 | S8: =COMPLEX(O8,P8) -> 0,0581+0,1763i | T8: =IMDIV(1,S8) -> 1,68614488076547-5,11647749533481i | U8: =COMPLEX(A8,R8) -> 0,0187i
A9: 0 | B9: 4 | C9: 6 | D9: 0.0119 | E9: 0.0414 | F9: 0.009 | G9: 0 | H9: 0 | I9: 0 | J9: 0 | K9: 0 | L9: 1 | M9: -360 | N9: 360; | O9: =SUBSTITUTE(D9,".",",") -> 0,0119 | P9: =SUBSTITUTE(E9,".",",") -> 0,0414 | Q9: =SUBSTITUTE(F9,".",",") -> 0,009 | R9: =Q9/2 -> 0.0045 | S9: =COMPLEX(O9,P9) -> 0,0119+0,0414i | T9: =IMDIV(1,S9) -> 6,41312373017456-22,3112035654812i | U9: =COMPLEX(A9,R9) -> 0,0045i
A10: 0 | B10: 5 | C10: 7 | D10: 0.046 | E10: 0.116 | F10: 0.0204 | G10: 0 | H10: 0 | I10: 0 | J10: 0 | K10: 0 | L10: 1 | M10: -360 | N10: 360; | O10: =SUBSTITUTE(D10,".",",") -> 0,046 | P10: =SUBSTITUTE(E10,".",",") -> 0,116 | Q10: =SUBSTITUTE(F10,".",",") -> 0,0204 | R10: =Q10/2 -> 0.0102 | S10: =COMPLEX(O10,P10) -> 0,046+0,116i | T10: =IMDIV(1,S10) -> 2,95402003596198-7,4492679167737i | U10: =COMPLEX(A10,R10) -> 0,0102i
A11: 0 | B11: 6 | C11: 7 | D11: 0.0267 | E11: 0.082 | F11: 0.017 | G11: 0 | H11: 0 | I11: 0 | J11: 0 | K11: 0 | L11: 1 | M11: -360 | N11: 360; | O11: =SUBSTITUTE(D11,".",",") -> 0,0267 | P11: =SUBSTITUTE(E11,".",",") -> 0,082 | Q11: =SUBSTITUTE(F11,".",",") -> 0,017 | R11: =Q11/2 -> 0.0085 | S11: =COMPLEX(O11,P11) -> 0,0267+0,082i | T11: =IMDIV(1,S11) -> 3,59021042398099-11,0261144107281i | U11: =COMPLEX(A11,R11) -> 0,0085i
A12: 0 | B12: 6 | C12: 8 | D12: 0.012 | E12: 0.042 | F12: 0.009 | G12: 0 | H12: 0 | I12: 0 | J12: 0 | K12: 0 | L12: 1 | M12: -360 | N12: 360; | O12: =SUBSTITUTE(D12,".",",") -> 0,012 | P12: =SUBSTITUTE(E12,".",",") -> 0,042 | Q12: =SUBSTITUTE(F12,".",",") -> 0,009 | R12: =Q12/2 -> 0.0045 | S12: =COMPLEX(O12,P12) -> 0,012+0,042i | T12: =IMDIV(1,S12) -> 6,28930817610063-22,0125786163522i | U12: =COMPLEX(A12,R12) -> 0,0045i
A13: 0 | B13: 6 | C13: 9 | D13: 0 | E13: 0.208 | F13: 0 | G13: 0 | H13: 0 | I13: 0 | J13: 0.978 | K13: 0 | L13: 1 | M13: -360 | N13: 360; | O13: =SUBSTITUTE(D13,".",",") -> 0 | P13: =SUBSTITUTE(E13,".",",") -> 0,208 | Q13: =SUBSTITUTE(F13,".",",") -> 0 | R13: =Q13/2 -> 0 | S13: =COMPLEX(O13,P13) -> 0,208i | T13: =IMDIV(1,S13) -> -4,80769230769231i | U13: =COMPLEX(A13,R13) -> 0
A14: 0 | B14: 6 | C14: 10 | D14: 0 | E14: 0.556 | F14: 0 | G14: 0 | H14: 0 | I14: 0 | J14: 0.969 | K14: 0 | L14: 1 | M14: -360 | N14: 360; | O14: =SUBSTITUTE(D14,".",",") -> 0 | P14: =SUBSTITUTE(E14,".",",") -> 0,556 | Q14: =SUBSTITUTE(F14,".",",") -> 0 | R14: =Q14/2 -> 0 | S14: =COMPLEX(O14,P14) -> 0,556i | T14: =IMDIV(1,S14) -> -1,79856115107914i | U14: =COMPLEX(A14,R14) -> 0
A15: 0 | B15: 9 | C15: 11 | D15: 0 | E15: 0.208 | F15: 0 | G15: 0 | H15: 0 | I15: 0 | J15: 0 | K15: 0 | L15: 1 | M15: -360 | N15: 360; | O15: =SUBSTITUTE(D15,".",",") -> 0 | P15: =SUBSTITUTE(E15,".",",") -> 0,208 | Q15: =SUBSTITUTE(F15,".",",") -> 0 | R15: =Q15/2 -> 0 | S15: =COMPLEX(O15,P15) -> 0,208i | T15: =IMDIV(1,S15) -> -4,80769230769231i | U15: =COMPLEX(A15,R15) -> 0
A16: 0 | B16: 9 | C16: 10 | D16: 0 | E16: 0.11 | F16: 0 | G16: 0 | H16: 0 | I16: 0 | J16: 0 | K16: 0 | L16: 1 | M16: -360 | N16: 360; | O16: =SUBSTITUTE(D16,".",",") -> 0 | P16: =SUBSTITUTE(E16,".",",") -> 0,11 | Q16: =SUBSTITUTE(F16,".",",") -> 0 | R16: =Q16/2 -> 0 | S16: =COMPLEX(O16,P16) -> 0,11i | T16: =IMDIV(1,S16) -> -9,09090909090909i | U16: =COMPLEX(A16,R16) -> 0
A17: 0 | B17: 4 | C17: 12 | D17: 0 | E17: 0.256 | F17: 0 | G17: 0 | H17: 0 | I17: 0 | J17: 0.932 | K17: 0 | L17: 1 | M17: -360 | N17: 360; | O17: =SUBSTITUTE(D17,".",",") -> 0 | P17: =SUBSTITUTE(E17,".",",") -> 0,256 | Q17: =SUBSTITUTE(F17,".",",") -> 0 | R17: =Q17/2 -> 0 | S17: =COMPLEX(O17,P17) -> 0,256i | T17: =IMDIV(1,S17) -> -3,90625i | U17: =COMPLEX(A17,R17) -> 0
A18: 0 | B18: 12 | C18: 13 | D18: 0 | E18: 0.14 | F18: 0 | G18: 0 | H18: 0 | I18: 0 | J18: 0 | K18: 0 | L18: 1 | M18: -360 | N18: 360; | O18: =SUBSTITUTE(D18,".",",") -> 0 | P18: =SUBSTITUTE(E18,".",",") -> 0,14 | Q18: =SUBSTITUTE(F18,".",",") -> 0 | R18: =Q18/2 -> 0 | S18: =COMPLEX(O18,P18) -> 0,14i | T18: =IMDIV(1,S18) -> -7,14285714285714i | U18: =COMPLEX(A18,R18) -> 0
A19: 0 | B19: 12 | C19: 14 | D19: 0.1231 | E19: 0.2559 | F19: 0 | G19: 0 | H19: 0 | I19: 0 | J19: 0 | K19: 0 | L19: 1 | M19: -360 | N19: 360; | O19: =SUBSTITUTE(D19,".",",") -> 0,1231 | P19: =SUBSTITUTE(E19,".",",") -> 0,2559 | Q19: =SUBSTITUTE(F19,".",",") -> 0 | R19: =Q19/2 -> 0 | S19: =COMPLEX(O19,P19) -> 0,1231+0,2559i | T19: =IMDIV(1,S19) -> 1,52656760883956-3,17342527296542i | U19: =COMPLEX(A19,R19) -> 0
A20: 0 | B20: 12 | C20: 15 | D20: 0.0662 | E20: 0.1304 | F20: 0 | G20: 0 | H20: 0 | I20: 0 | J20: 0 | K20: 0 | L20: 1 | M20: -360 | N20: 360; | O20: =SUBSTITUTE(D20,".",",") -> 0,0662 | P20: =SUBSTITUTE(E20,".",",") -> 0,1304 | Q20: =SUBSTITUTE(F20,".",",") -> 0 | R20: =Q20/2 -> 0 | S20: =COMPLEX(O20,P20) -> 0,0662+0,1304i | T20: =IMDIV(1,S20) -> 3,09539618265643-6,09727586432626i | U20: =COMPLEX(A20,R20) -> 0
A21: 0 | B21: 12 | C21: 16 | D21: 0.0945 | E21: 0.1987 | F21: 0 | G21: 0 | H21: 0 | I21: 0 | J21: 0 | K21: 0 | L21: 1 | M21: -360 | N21: 360; | O21: =SUBSTITUTE(D21,".",",") -> 0,0945 | P21: =SUBSTITUTE(E21,".",",") -> 0,1987 | Q21: =SUBSTITUTE(F21,".",",") -> 0 | R21: =Q21/2 -> 0 | S21: =COMPLEX(O21,P21) -> 0,0945+0,1987i | T21: =IMDIV(1,S21) -> 1,95199779228017-4,10435937911185i | U21: =COMPLEX(A21,R21) -> 0
A22: 0 | B22: 14 | C22: 15 | D22: 0.221 | E22: 0.1997 | F22: 0 | G22: 0 | H22: 0 | I22: 0 | J22: 0 | K22: 0 | L22: 1 | M22: -360 | N22: 360; | O22: =SUBSTITUTE(D22,".",",") -> 0,221 | P22: =SUBSTITUTE(E22,".",",") -> 0,1997 | Q22: =SUBSTITUTE(F22,".",",") -> 0 | R22: =Q22/2 -> 0 | S22: =COMPLEX(O22,P22) -> 0,221+0,1997i | T22: =IMDIV(1,S22) -> 2,49095226399946-2,25087405936965i | U22: =COMPLEX(A22,R22) -> 0
A23: 0 | B23: 16 | C23: 17 | D23: 0.0524 | E23: 0.1923 | F23: 0 | G23: 0 | H23: 0 | I23: 0 | J23: 0 | K23: 0 | L23: 1 | M23: -360 | N23: 360; | O23: =SUBSTITUTE(D23,".",",") -> 0,0524 | P23: =SUBSTITUTE(E23,".",",") -> 0,1923 | Q23: =SUBSTITUTE(F23,".",",") -> 0 | R23: =Q23/2 -> 0 | S23: =COMPLEX(O23,P23) -> 0,0524+0,1923i | T23: =IMDIV(1,S23) -> 1,31906693635376-4,84077427215321i | U23: =COMPLEX(A23,R23) -> 0
A24: 0 | B24: 15 | C24: 18 | D24: 0.1073 | E24: 0.2185 | F24: 0 | G24: 0 | H24: 0 | I24: 0 | J24: 0 | K24: 0 | L24: 1 | M24: -360 | N24: 360; | O24: =SUBSTITUTE(D24,".",",") -> 0,1073 | P24: =SUBSTITUTE(E24,".",",") -> 0,2185 | Q24: =SUBSTITUTE(F24,".",",") -> 0 | R24: =Q24/2 -> 0 | S24: =COMPLEX(O24,P24) -> 0,1073+0,2185i | T24: =IMDIV(1,S24) -> 1,8108011504072-3,6874189316307i | U24: =COMPLEX(A24,R24) -> 0
A25: 0 | B25: 18 | C25: 19 | D25: 0.0639 | E25: 0.1292 | F25: 0 | G25: 0 | H25: 0 | I25: 0 | J25: 0 | K25: 0 | L25: 1 | M25: -360 | N25: 360; | O25: =SUBSTITUTE(D25,".",",") -> 0,0639 | P25: =SUBSTITUTE(E25,".",",") -> 0,1292 | Q25: =SUBSTITUTE(F25,".",",") -> 0 | R25: =Q25/2 -> 0 | S25: =COMPLEX(O25,P25) -> 0,0639+0,1292i | T25: =IMDIV(1,S25) -> 3,07568643400872-6,21875879927897i | U25: =COMPLEX(A25,R25) -> 0
A26: 0 | B26: 19 | C26: 20 | D26: 0.034 | E26: 0.068 | F26: 0 | G26: 0 | H26: 0 | I26: 0 | J26: 0 | K26: 0 | L26: 1 | M26: -360 | N26: 360; | O26: =SUBSTITUTE(D26,".",",") -> 0,034 | P26: =SUBSTITUTE(E26,".",",") -> 0,068 | Q26: =SUBSTITUTE(F26,".",",") -> 0 | R26: =Q26/2 -> 0 | S26: =COMPLEX(O26,P26) -> 0,034+0,068i | T26: =IMDIV(1,S26) -> 5,88235294117647-11,7647058823529i | U26: =COMPLEX(A26,R26) -> 0
A27: 0 | B27: 10 | C27: 20 | D27: 0.0936 | E27: 0.209 | F27: 0 | G27: 0 | H27: 0 | I27: 0 | J27: 0 | K27: 0 | L27: 1 | M27: -360 | N27: 360; | O27: =SUBSTITUTE(D27,".",",") -> 0,0936 | P27: =SUBSTITUTE(E27,".",",") -> 0,209 | Q27: =SUBSTITUTE(F27,".",",") -> 0 | R27: =Q27/2 -> 0 | S27: =COMPLEX(O27,P27) -> 0,0936+0,209i | T27: =IMDIV(1,S27) -> 1,78483031526663-3,98535828943083i | U27: =COMPLEX(A27,R27) -> 0
A28: 0 | B28: 10 | C28: 17 | D28: 0.0324 | E28: 0.0845 | F28: 0 | G28: 0 | H28: 0 | I28: 0 | J28: 0 | K28: 0 | L28: 1 | M28: -360 | N28: 360; | O28: =SUBSTITUTE(D28,".",",") -> 0,0324 | P28: =SUBSTITUTE(E28,".",",") -> 0,0845 | Q28: =SUBSTITUTE(F28,".",",") -> 0 | R28: =Q28/2 -> 0 | S28: =COMPLEX(O28,P28) -> 0,0324+0,0845i | T28: =IMDIV(1,S28) -> 3,95603912571535-10,3174477198441i | U28: =COMPLEX(A28,R28) -> 0
A29: 0 | B29: 10 | C29: 21 | D29: 0.0348 | E29: 0.0749 | F29: 0 | G29: 0 | H29: 0 | I29: 0 | J29: 0 | K29: 0 | L29: 1 | M29: -360 | N29: 360; | O29: =SUBSTITUTE(D29,".",",") -> 0,0348 | P29: =SUBSTITUTE(E29,".",",") -> 0,0749 | Q29: =SUBSTITUTE(F29,".",",") -> 0 | R29: =Q29/2 -> 0 | S29: =COMPLEX(O29,P29) -> 0,0348+0,0749i | T29: =IMDIV(1,S29) -> 5,10185382015965-10,9807141129298i | U29: =COMPLEX(A29,R29) -> 0
A30: 0 | B30: 10 | C30: 22 | D30: 0.0727 | E30: 0.1499 | F30: 0 | G30: 0 | H30: 0 | I30: 0 | J30: 0 | K30: 0 | L30: 1 | M30: -360 | N30: 360; | O30: =SUBSTITUTE(D30,".",",") -> 0,0727 | P30: =SUBSTITUTE(E30,".",",") -> 0,1499 | Q30: =SUBSTITUTE(F30,".",",") -> 0 | R30: =Q30/2 -> 0 | S30: =COMPLEX(O30,P30) -> 0,0727+0,1499i | T30: =IMDIV(1,S30) -> 2,6193195533826-5,40077030332945i | U30: =COMPLEX(A30,R30) -> 0
... A37: 0 | B37: 25 | C37: 27 | D37: 0.1093 | E37: 0.2087 | F37: 0 | G37: 0 | H37: 0 | I37: 0 | J37: 0 | K37: 0 | L37: 1 | M37: -360 | N37: 360; | O37: =SUBSTITUTE(D37,".",",") -> 0,1093 | P37: =SUBSTITUTE(E37,".",",") -> 0,2087 | Q37: =SUBSTITUTE(F37,".",",") -> 0 | R37: =Q37/2 -> 0 | S37: =COMPLEX(O37,P37) -> 0,1093+0,2087i | T37: =IMDIV(1,S37) -> 1,96929201699825-3,76021266191706i | U37: =COMPLEX(A37,R37) -> 0
A38: 0 | B38: 28 | C38: 27 | D38: 0 | E38: 0.396 | F38: 0 | G38: 0 | H38: 0 | I38: 0 | J38: 0.968 | K38: 0 | L38: 1 | M38: -360 | N38: 360; | O38: =SUBSTITUTE(D38,".",",") -> 0 | P38: =SUBSTITUTE(E38,".",",") -> 0,396 | Q38: =SUBSTITUTE(F38,".",",") -> 0 | R38: =Q38/2 -> 0 | S38: =COMPLEX(O38,P38) -> 0,396i | T38: =IMDIV(1,S38) -> -2,52525252525253i | U38: =COMPLEX(A38,R38) -> 0
A39: 0 | B39: 27 | C39: 29 | D39: 0.2198 | E39: 0.4153 | F39: 0 | G39: 0 | H39: 0 | I39: 0 | J39: 0 | K39: 0 | L39: 1 | M39: -360 | N39: 360; | O39: =SUBSTITUTE(D39,".",",") -> 0,2198 | P39: =SUBSTITUTE(E39,".",",") -> 0,4153 | Q39: =SUBSTITUTE(F39,".",",") -> 0 | R39: =Q39/2 -> 0 | S39: =COMPLEX(O39,P39) -> 0,2198+0,4153i | T39: =IMDIV(1,S39) -> 0,99553355095268-1,88100584035782i | U39: =COMPLEX(A39,R39) -> 0
A40: 0 | B40: 27 | C40: 30 | D40: 0.3202 | E40: 0.6027 | F40: 0 | G40: 0 | H40: 0 | I40: 0 | J40: 0 | K40: 0 | L40: 1 | M40: -360 | N40: 360; | O40: =SUBSTITUTE(D40,".",",") -> 0,3202 | P40: =SUBSTITUTE(E40,".",",") -> 0,6027 | Q40: =SUBSTITUTE(F40,".",",") -> 0 | R40: =Q40/2 -> 0 | S40: =COMPLEX(O40,P40) -> 0,3202+0,6027i | T40: =IMDIV(1,S40) -> 0,687455902827657-1,29397149479772i | U40: =COMPLEX(A40,R40) -> 0
A41: 0 | B41: 29 | C41: 30 | D41: 0.2399 | E41: 0.4533 | F41: 0 | G41: 0 | H41: 0 | I41: 0 | J41: 0 | K41: 0 | L41: 1 | M41: -360 | N41: 360; | O41: =SUBSTITUTE(D41,".",",") -> 0,2399 | P41: =SUBSTITUTE(E41,".",",") -> 0,4533 | Q41: =SUBSTITUTE(F41,".",",") -> 0 | R41: =Q41/2 -> 0 | S41: =COMPLEX(O41,P41) -> 0,2399+0,4533i | T41: =IMDIV(1,S41) -> 0,912053207032276-1,72335856084923i | U41: =COMPLEX(A41,R41) -> 0
A42: 0 | B42: 8 | C42: 28 | D42: 0.0636 | E42: 0.2 | F42: 0.0428 | G42: 0 | H42: 0 | I42: 0 | J42: 0 | K42: 0 | L42: 1 | M42: -360 | N42: 360; | O42: =SUBSTITUTE(D42,".",",") -> 0,0636 | P42: =SUBSTITUTE(E42,".",",") -> 0,2 | Q42: =SUBSTITUTE(F42,".",",") -> 0,0428 | R42: =Q42/2 -> 0.0214 | S42: =COMPLEX(O42,P42) -> 0,0636+0,2i | T42: =IMDIV(1,S42) -> 1,44397906139545-4,54081465847625i | U42: =COMPLEX(A42,R42) -> 0,0214i
A43: 0 | B43: 6 | C43: 28 | D43: 0.0169 | E43: 0.0599 | F43: 0.013 | G43: 0 | H43: 0 | I43: 0 | J43: 0 | K43: 0 | L43: 1 | M43: -360 | N43: 360; | O43: =SUBSTITUTE(D43,".",",") -> 0,0169 | P43: =SUBSTITUTE(E43,".",",") -> 0,0599 | Q43: =SUBSTITUTE(F43,".",",") -> 0,013 | R43: =Q43/2 -> 0.0065 | S43: =COMPLEX(O43,P43) -> 0,0169+0,0599i | T43: =IMDIV(1,S43) -> 4,36284405801292-15,4635715428979i | U43: =COMPLEX(A43,R43) -> 0,0065i

Sheet Generacion
B2: Generacion
B3: Bus | C3: Pg | D3: Qg | E3: Qmax | F3: Qmin | G3: Vg | H3: mBase | I3: status | J3: Pmax
B4: 1 | C4: 260.2 | D4: -16.1 | E4: 10 | F4: 0 | G4: 1.06 | H4: 100 | I4: 1 | J4: 360.2
B5: 2 | C5: 40 | D5: 50 | E5: 50 | F5: -40 | G5: 1045 | H5: 100 | I5: 1 | J5: 140
B6: 5 | C6: 0 | D6: 37 | E6: 40 | F6: -40 | G6: 1.01 | H6: 100 | I6: 1 | J6: 100
B7: 8 | C7: 0 | D7: 37.3 | E7: 40 | F7: -10 | G7: 1.01 | H7: 100 | I7: 1 | J7: 100
B8: 11 | C8: 0 | D8: 16.2 | E8: 24 | F8: -6 | G8: 1082 | H8: 100 | I8: 1 | J8: 100
B9: 13 | C9: 0 | D9: 10.6 | E9: 24 | F9: -6 | G9: 1071 | H9: 100 | I9: 1 | J9: 100

Sheet DATOS ESPERADOS
B1: 1 | C1: 3 | D1: 0 | E1: 0 | F1: 0 | G1: 0 | H1: 1 | I1: 1.06 | J1: 0 | K1: 132 | L1: 1 | M1: 1.06 | N1: 0.94; | P1: 1 | Q1: =SUBSTITUTE(I1,".",",") -> 1,06
B2: 2 | C2: 2 | D2: 21.7 | E2: 12.7 | F2: 0 | G2: 0 | H2: 1 | I2: 1043 | J2: -5.48 | K2: 132 | L2: 1 | M2: 1.06 | N2: 0.94; | P2: 2 | Q2: 1.043
B3: 3 | C3: 1 | D3: 2.4 | E3: 1.2 | F3: 0 | G3: 0 | H3: 1 | I3: 1021 | J3: -7.96 | K3: 132 | L3: 1 | M3: 1.06 | N3: 0.94; | P3: 3 | Q3: 1.043
B4: 4 | C4: 1 | D4: 7.6 | E4: 1.6 | F4: 0 | G4: 0 | H4: 1 | I4: 1012 | J4: -9.62 | K4: 132 | L4: 1 | M4: 1.06 | N4: 0.94; | P4: 4 | Q4: 1.021
B5: 5 | C5: 2 | D5: 94.2 | E5: 19 | F5: 0 | G5: 0 | H5: 1 | I5: 1.01 | J5: -14.37 | K5: 132 | L5: 1 | M5: 1.06 | N5: 0.94; | P5: 5 | Q5: 1.01
B6: 6 | C6: 1 | D6: 0 | E6: 0 | F6: 0 | G6: 0 | H6: 1 | I6: 1.01 | J6: -11.34 | K6: 132 | L6: 1 | M6: 1.06 | N6: 0.94; | P6: 6 | Q6: 1.01
B7: 7 | C7: 1 | D7: 22.8 | E7: 10.9 | F7: 0 | G7: 0 | H7: 1 | I7: 1002 | J7: -13.12 | K7: 132 | L7: 1 | M7: 1.06 | N7: 0.94; | P7: 7 | Q7: 1.002
B8: 8 | C8: 2 | D8: 30 | E8: 30 | F8: 0 | G8: 0 | H8: 1 | I8: 1.01 | J8: -12.1 | K8: 132 | L8: 1 | M8: 1.06 | N8: 0.94; | P8: 8 | Q8: 1.01
B9: 9 | C9: 1 | D9: 0 | E9: 0 | F9: 0 | G9: 0 | H9: 1 | I9: 1051 | J9: -14.38 | K9: 1 | L9: 1 | M9: 1.06 | N9: 0.94; | P9: 9 | Q9: 1.051
B10: 10 | C10: 1 | D10: 5.8 | E10: 2 | F10: 0 | G10: 19 | H10: 1 | I10: 1045 | J10: -15.97 | K10: 33 | L10: 1 | M10: 1.06 | N10: 0.94; | P10: 10 | Q10: 1.045
B11: 11 | C11: 2 | D11: 0 | E11: 0 | F11: 0 | G11: 0 | H11: 1 | I11: 1082 | J11: -14.39 | K11: 11 | L11: 1 | M11: 1.06 | N11: 0.94; | P11: 11 | Q11: 1.082
B12: 12 | C12: 1 | D12: 11.2 | E12: 7.5 | F12: 0 | G12: 0 | H12: 1 | I12: 1057 | J12: -15.24 | K12: 33 | L12: 1 | M12: 1.06 | N12: 0.94; | P12: 12 | Q12: 1.057
B13: 13 | C13: 2 | D13: 0 | E13: 0 | F13: 0 | G13: 0 | H13: 1 | I13: 1071 | J13: -15.24 | K13: 11 | L13: 1 | M13: 1.06 | N13: 0.94; | P13: 13 | Q13: 1.071
B14: 14 | C14: 1 | D14: 6.2 | E14: 1.6 | F14: 0 | G14: 0 | H14: 1 | I14: 1042 | J14: -16.13 | K14: 33 | L14: 1 | M14: 1.06 | N14: 0.94; | P14: 14 | Q14: 1.042
B15: 15 | C15: 1 | D15: 8.2 | E15: 2.5 | F15: 0 | G15: 0 | H15: 1 | I15: 1038 | J15: -16.22 | K15: 33 | L15: 1 | M15: 1.06 | N15: 0.94; | P15: 15 | Q15: 1.038
B16: 16 | C16: 1 | D16: 3.5 | E16: 1.8 | F16: 0 | G16: 0 | H16: 1 | I16: 1045 | J16: -15.83 | K16: 33 | L16: 1 | M16: 1.06 | N16: 0.94; | P16: 16 | Q16: 1.045
B17: 17 | C17: 1 | D17: 9 | E17: 5.8 | F17: 0 | G17: 0 | H17: 1 | I17: 1.04 | J17: -16.14 | K17: 33 | L17: 1 | M17: 1.06 | N17: 0.94; | P17: 17 | Q17: 1.04
B18: 18 | C18: 1 | D18: 3.2 | E18: 0.9 | F18: 0 | G18: 0 | H18: 1 | I18: 1028 | J18: -16.82 | K18: 33 | L18: 1 | M18: 1.06 | N18: 0.94; | P18: 18 | Q18: 1.028
B19: 19 | C19: 1 | D19: 9.5 | E19: 3.4 | F19: 0 | G19: 0 | H19: 1 | I19: 1026 | J19: -17 | K19: 33 | L19: 1 | M19: 1.06 | N19: 0.94; | P19: 19 | Q19: 1.026
B20: 20 | C20: 1 | D20: 2.2 | E20: 0.7 | F20: 0 | G20: 0 | H20: 1 | I20: 1.03 | J20: -16.8 | K20: 33 | L20: 1 | M20: 1.06 | N20: 0.94; | P20: 20 | Q20: 1.03
B21: 21 | C21: 1 | D21: 17.5 | E21: 11.2 | F21: 0 | G21: 0 | H21: 1 | I21: 1033 | J21: -16.42 | K21: 33 | L21: 1 | M21: 1.06 | N21: 0.94; | P21: 21 | Q21: 1.033
B22: 22 | C22: 1 | D22: 0 | E22: 0 | F22: 0 | G22: 0 | H22: 1 | I22: 1033 | J22: -16.41 | K22: 33 | L22: 1 | M22: 1.06 | N22: 0.94; | P22: 22 | Q22: 1.033
B23: 23 | C23: 1 | D23: 3.2 | E23: 1.6 | F23: 0 | G23: 0 | H23: 1 | I23: 1027 | J23: -16.61 | K23: 33 | L23: 1 | M23: 1.06 | N23: 0.94; | P23: 23 | Q23: 1.027
B24: 24 | C24: 1 | D24: 8.7 | E24: 6.7 | F24: 0 | G24: 4.3 | H24: 1 | I24: 1021 | J24: -16.78 | K24: 33 | L24: 1 | M24: 1.06 | N24: 0.94; | P24: 24 | Q24: 1.021
B25: 25 | C25: 1 | D25: 0 | E25: 0 | F25: 0 | G25: 0 | H25: 1 | I25: 1017 | J25: -16.35 | K25: 33 | L25: 1 | M25: 1.06 | N25: 0.94; | P25: 25 | Q25: 1.017
B26: 26 | C26: 1 | D26: 3.5 | E26: 2.3 | F26: 0 | G26: 0 | H26: 1 | I26: 1 | J26: -16.77 | K26: 33 | L26: 1 | M26: 1.06 | N26: 0.94; | P26: 26 | Q26: 1
B27: 27 | C27: 1 | D27: 0 | E27: 0 | F27: 0 | G27: 0 | H27: 1 | I27: 1023 | J27: -15.82 | K27: 33 | L27: 1 | M27: 1.06 | N27: 0.94; | P27: 27 | Q27: 1.023
B28: 28 | C28: 1 | D28: 0 | E28: 0 | F28: 0 | G28: 0 | H28: 1 | I28: 1007 | J28: -11.97 | K28: 132 | L28: 1 | M28: 1.06 | N28: 0.94; | P28: 28 | Q28: 1.007
B29: 29 | C29: 1 | D29: 2.4 | E29: 0.9 | F29: 0 | G29: 0 | H29: 1 | I29: 1003 | J29: -17.06 | K29: 33 | L29: 1 | M29: 1.06 | N29: 0.94; | P29: 29 | Q29: 1.003
B30: 30 | C30: 1 | D30: 10.6 | E30: 1.9 | F30: 0 | G30: 0 | H30: 1 | I30: 0.992 | J30: -17.94 | K30: 33 | L30: 1 | M30: 1.06 | N30: 0.94; | P30: 30 | Q30: 0.992

Sheet Hoja2
C2: RESULTADOS CASO BASE | P2: Type | Q2: No. | R2: MW | S2: % | T2: MVAr | U2: %
C3: Type | D3: No. | E3: Voltage (pu) | F3: Angle (deg) | G3: Pg (MW) | H3: Qg (MVAr) | I3: Pl(MW) | J3: Ql (MVAr) | K3: P neta | L3: Q neta | O3: 1 | P3: Línea | Q3: 1–2: | R3: 5.213 | S3: -0.29688 | T3: 15.61 | U3: -0.23064
C4: 1 | D4: Slack | E4: 1.06 | F4: 0 | G4: 260.2 | H4: -20.418 | I4: 0 | J4: 0 | K4: =G4-I4 -> 260.2 | L4: =H4-J4 -> -20.418 | O4: 2 | P4: Línea | Q4: 1–3: | R4: 3.108 | S4: -0.177 | T4: 11.36 | U4: -0.16785
C5: 2 | D5: PV | E5: 1.045 | F5: -5.3782 | G5: 40 | H5: 56.069 | I5: 21.7 | J5: 12.7 | K5: =G5-I5 -> 18.3 | L5: =H5-J5 -> 43.369 | O5: 3 | P5: Línea | Q5: 2–5: | R5: 2.943 | S5: -0.16761 | T5: 12.36 | U5: -0.18262
C6: 3 | D6: PQ | E6: 1.0212 | F6: -7.5287 | G6: 0 | H6: 0 | I6: 2.4 | J6: 1.2 | K6: =G6-I6 -> -2.4 | L6: =H6-J6 -> -1.2 | O6: 4 | P6: Línea | Q6: 2–6: | R6: 1.946 | S6: -0.11083 | T6: 5.9 | U6: -0.08717
C7: 4 | D7: PQ | E7: 1.0123 | F7: -9.2794 | G7: 0 | H7: 0 | I7: 7.6 | J7: 1.6 | K7: =G7-I7 -> -7.6 | L7: =H7-J7 -> -1.6 | O7: 5 | P7: Línea | Q7: 2–4: | R7: 1.018 | S7: -0.05798 | T7: 3.1 | U7: -0.0458
C8: 5 | D8: PV | E8: 1.01 | F8: -14.1488 | G8: 0 | H8: 35.659 | I8: 94.2 | J8: 19 | K8: =G8-I8 -> -94.2 | L8: =H8-J8 -> 16.659 | O8: 6 | P8: Línea | Q8: 3–4: | R8: 0.856 | S8: -0.04875 | T8: 2.46 | U8: -0.03635
C9: 6 | D9: PQ | E9: 1.0106 | F9: -11.055 | G9: 0 | H9: 0 | I9: 0 | J9: 0 | K9: =G9-I9 -> 0 | L9: =H9-J9 -> 0 | O9: 7 | P9: Línea | Q9: 4–6: | R9: 0.632 | S9: -0.03599 | T9: 2.2 | U9: -0.03251
C10: 7 | D10: PQ | E10: 1.0026 | F10: -12.8523 | G10: 0 | H10: 0 | I10: 22.8 | J10: 10.9 | K10: =G10-I10 -> -22.8 | L10: =H10-J10 -> -10.9 | O10: 8 | P10: Línea | Q10: 6–7: | R10: 0.381 | S10: -0.0217 | T10: 1.17 | U10: -0.01729
C11: 8 | D11: PV | E11: 1.01 | F11: -11.7974 | G11: 0 | H11: 36.111 | I11: 30 | J11: 30 | K11: =G11-I11 -> -30 | L11: =H11-J11 -> 6.111 | O11: 9 | P11: Línea | Q11: 12–15: | R11: 0.217 | S11: -0.01236 | T11: 0.43 | U11: -0.00635
C12: 9 | D12: PQ | E12: 1.0511 | F12: -14.098 | G12: 0 | H12: 0 | I12: 0 | J12: 0 | K12: =G12-I12 -> 0 | L12: =H12-J12 -> 0 | O12: 10 | P12: Línea | Q12: 5–7: | R12: 0.169 | S12: -0.00962 | T12: 0.43 | U12: -0.00635
C13: 10 | D13: PQ | E13: 1.0454 | F13: -15.6882 | G13: 0 | H13: 0 | I13: 5.8 | J13: 2 | K13: =G13-I13 -> -5.8 | L13: =H13-J13 -> -2 | O13: 11 | P13: Línea | Q13: 27–30: | R13: 0.162 | S13: -0.00923 | T13: 0.31 | U13: -0.00458
C14: 11 | D14: PV | E14: 1.082 | F14: -14.098 | G14: 0 | H14: 16.057 | I14: 0 | J14: 0 | K14: =G14-I14 -> 0 | L14: =H14-J14 -> 16.057 | O14: 12 | P14: Línea | Q14: 10–21: | R14: 0.111 | S14: -0.00632 | T14: 0.24 | U14: -0.00355
C15: 12 | D15: PQ | E15: 1.0573 | F15: -14.9329 | G15: 0 | H15: 0 | I15: 11.2 | J15: 7.5 | K15: =G15-I15 -> -11.2 | L15: =H15-J15 -> -7.5 | O15: 13 | P15: Línea | Q15: 6–8: | R15: 0.108 | S15: -0.00615 | T15: 0.38 | U15: -0.00561
... C33: 30 | D33: PQ | E33: 0.9922 | F33: -17.6416 | G33: 0 | H33: 0 | I33: 10.6 | J33: 1.9 | K33: =G33-I33 -> -10.6 | L33: =H33-J33 -> -1.9 | O33: 31 | P33: Línea | Q33: 8–28: | R33: 0.002 | S33: -0.00011 | T33: 0.01 | U33: -0.00015
O34: 32 | P34: Línea | Q34: 21–22: | R34: 0.001 | S34: -6e-05 | T34: 0 | U34: 0
O35: 33 | P35: Línea | Q35: 6–9: | R35: 0 | S35: 0 | T35: 1.62 | U35: -0.02394
O36: 34 | P36: Línea | Q36: 6–10: | R36: 0 | S36: 0 | T36: 1.28 | U36: -0.01891
O37: 35 | P37: Línea | Q37: 9–11: | R37: 0 | S37: 0 | T37: 0.46 | U37: -0.0068
O38: 36 | P38: Línea | Q38: 6-28: | R38: 0 | S38: 0 | T38: 0.8 | U38: -0.01182
O39: 37 | P39: Línea | Q39: 4–12: | R39: 0 | S39: 0 | T39: 4.69 | U39: -0.0693
O40: 38 | P40: Línea | Q40: 12–13: | R40: 0 | S40: 0 | T40: 0.13 | U40: -0.00192
O41: 39 | P41: Línea | Q41: 28–27: | R41: 0 | S41: 0 | T41: 1.29 | U41: -0.01906
O42: 40 | P42: Línea | Q42: 10–17: | R42: 0.014 | S42: -0.0008 | T42: 0.04 | U42: -0.00059
O43: 41 | P43: Línea | Q43: 19–20: | R43: 0.017 | S43: -0.00097 | T43: 0.03 | U43: -0.00044

Sheet Caso A
B2: RESULTADOS ESPERADOS | R2: RESULTADOS OBTENIDOS
B3: Bus | C3: Type | D3: Voltage | E3: Angle | F3: Pg | G3: Qg | H3: Pl | I3: Ql | J3: Voltaje | K3: Angle | L3: Pg | M3: Qg | N3: Pl | O3: Ql | R3: Bus | S3: Type | T3: Voltage | U3: Angle | V3: Pg | W3: Qg | X3: Pl | Y3: Ql | Z3: Voltaje | AA3: Angle | AB3: Pg | AC3: Qg | AD3: Pl | AE3: Ql | AF3: PG-Pl | AG3: QG-Ql | AL3: Rango CREG | AQ3: bus | AR3: Voltaje(pu) | AS3: Angle | AV3: fbus | AW3: tbus | AX3: y(f,t)
D4: (pu) | E4: (deg) | F4: (MW) | G4: (MVAr) | H4: (MW) | I4: (MVAr) | J4: (pu) | K4: (deg) | L4: (MW) | M4: (MVAr) | N4: (MW) | O4: (MVAr) | T4: (pu) | U4: (deg) | V4: (MW) | W4: (MVAr) | X4: (MW) | Y4: (MVAr) | Z4: (pu) | AA4: (deg) | AB4: (MW) | AC4: (MVAr) | AD4: (MW) | AE4: (MVAr) | AF4: (MW) | AG4: (MVAr) | AI4: V Error [%] | AJ4: Diferencia V angle | AL4: limite superior [kV] | AM4: limite inferior[kV] | AN4: V[KV] | AT4: voltaje | AU4: angulo | BA4: from | BB4: to | BC4: P_from (MW) | BD4: Q_from (MVAr) | BE4: P_to (MW) | BF4: Q_to (MVAr) | BG4: P_loss (MW) | BH4: Q_loss (MVAr)
B5: 1 | C5: Slack | D5: 1.060 | E5: 0.000* | F5: 260.96 | G5: -20.42 | H5: - | I5: - | J5: =SUBSTITUTE(D5,".",",") -> 1,060 | K5: 0 | L5: =SUBSTITUTE(F5,".",",") -> 260,96 | M5: =SUBSTITUTE(G5,".",",") -> -20,42 | N5: =SUBSTITUTE(H5,".",",") -> - | O5: =SUBSTITUTE(I5,".",",") -> - | R5: 1 | S5: Slack | T5: 1.0600 | U5: 0.0000 | V5: 260.200 | W5: -20.418 | X5: 0.000 | Y5: 0.000 | Z5: =SUBSTITUTE(T5,".",",") -> 1,0600 | AA5: =SUBSTITUTE(U5,".",",") -> 0,0000 | AB5: =SUBSTITUTE(V5,".",",") -> 260,200 | AC5: =SUBSTITUTE(W5,".",",") -> -20,418 | AD5: 0 | AE5: 0 | AF5: =AB5-AD5 -> 260200 | AG5: =AC5-AE5 -> -20418 | AI5: 0,00% | AJ5: #VALUE! | AL5: =Nodos!L4*1.1 -> 145.2 | AM5: =Nodos!L4*0.9 -> 118.8 | AN5: =Z5*'DATOS ESPERADOS'!K1 -> 1399200 | AQ5: 1 | AR5: 1.06 | AS5: 0 | AT5: =AR5*'DATOS ESPERADOS'!K1 -> 139.92 | AU5: 0 | AV5: 1 | AW5: 2 | AX5: =[1]Sheet1!$B$2 -> (-5.224646179885656+15.646726840803398j) | AZ5: 1 | BA5: 1 | BB5: 2 | BC5: 173.30581 | BD5: -24.70245 | BE5: -168.09273 | BF5: 34.46529 | BG5: 5.213 | BH5: 15.61
B6: 2 | C6: PV | D6: 1.045 | E6: -5.378 | F6: 40.00 | G6: 56.07 | H6: 21.70 | I6: 12.70 | J6: =SUBSTITUTE(D6,".",",") -> 1,045 | K6: =SUBSTITUTE(E6,".",",") -> -5,378 | L6: =SUBSTITUTE(F6,".",",") -> 40,00 | M6: =SUBSTITUTE(G6,".",",") -> 56,07 | N6: =SUBSTITUTE(H6,".",",") -> 21,70 | O6: =SUBSTITUTE(I6,".",",") -> 12,70 | R6: 2 | S6: PV | T6: 1.0450 | U6: -5.3782 | V6: 40.000 | W6: 56.069 | X6: 21.700 | Y6: 12.700 | Z6: =SUBSTITUTE(T6,".",",") -> 1,0450 | AA6: =SUBSTITUTE(U6,".",",") -> -5,3782 | AB6: =SUBSTITUTE(V6,".",",") -> 40,000 | AC6: =SUBSTITUTE(W6,".",",") -> 56,069 | AD6: 21.7 | AE6: 12.7 | AF6: =AB6-AD6 -> 39978.3 | AG6: =AC6-AE6 -> 56056.3 | AI6: 0,00% | AJ6: 0,0002 | AL6: =Nodos!L5*1.1 -> 145.2 | AM6: =Nodos!L5*0.9 -> 118.8 | AN6: =Z6*'DATOS ESPERADOS'!K2 -> 1379400 | AQ6: 2 | AR6: 1.045 | AS6: -5.3782 | AT6: =AR6*'DATOS ESPERADOS'!K2 -> 137.94 | AU6: -5.3782 | AV6: 1 | AW6: 3 | AX6: =[1]Sheet1!$C$2 -> (-1.5408698687669766+5.631674830095234j) | AZ6: 2 | BA6: 1 | BB6: 3 | BC6: 87.64838 | BD6: 4.27114 | BE6: -84.54065 | BF6: 2.66764 | BG6: 3.108 | BH6: 11.36
B7: 3 | C7: PQ | D7: 1.021 | E7: -7.529 | F7: - | G7: - | H7: 2.40 | I7: 1.20 | J7: =SUBSTITUTE(D7,".",",") -> 1,021 | K7: =SUBSTITUTE(E7,".",",") -> -7,529 | L7: =SUBSTITUTE(F7,".",",") -> - | M7: =SUBSTITUTE(G7,".",",") -> - | N7: =SUBSTITUTE(H7,".",",") -> 2,40 | O7: =SUBSTITUTE(I7,".",",") -> 1,20 | R7: 3 | S7: PQ | T7: 1.0212 | U7: -7.5287 | V7: 0.000 | W7: --- | X7: 2.400 | Y7: 1.200 | Z7: =SUBSTITUTE(T7,".",",") -> 1,0212 | AA7: =SUBSTITUTE(U7,".",",") -> -7,5287 | AB7: =SUBSTITUTE(V7,".",",") -> 0,000 | AC7: 0 | AD7: 2.4 | AE7: 1.2 | AF7: =AB7-AD7 -> #VALUE! | AG7: =AC7-AE7 -> -1.2 | AI7: 0,02% | AJ7: -0,0003 | AL7: =Nodos!L6*1.1 -> 145.2 | AM7: =Nodos!L6*0.9 -> 118.8 | AN7: =Z7*'DATOS ESPERADOS'!K3 -> 1347984 | AQ7: 3 | AR7: 1.0212 | AS7: -7.5287 | AT7: =AR7*'DATOS ESPERADOS'!K3 -> 134.7984 | AU7: -7.5287 | AV7: 2 | AW7: 4 | AX7: =[1]Sheet1!$D$3 -> (-1.7055303166990268+5.197379228256508j) | AZ7: 3 | BA7: 2 | BB7: 4 | BC7: 43.65286 | BD7: 4.74978 | BE7: -42.63437 | BF7: -5.54094 | BG7: 1.018 | BH7: 3.1
B8: 4 | C8: PQ | D8: 1.012 | E8: -9.279 | F8: - | G8: - | H8: 7.60 | I8: 1.60 | J8: =SUBSTITUTE(D8,".",",") -> 1,012 | K8: =SUBSTITUTE(E8,".",",") -> -9,279 | L8: =SUBSTITUTE(F8,".",",") -> - | M8: =SUBSTITUTE(G8,".",",") -> - | N8: =SUBSTITUTE(H8,".",",") -> 7,60 | O8: =SUBSTITUTE(I8,".",",") -> 1,60 | R8: 4 | S8: PQ | T8: 1.0123 | U8: -9.2794 | V8: 0.000 | W8: --- | X8: 7.600 | Y8: 1.600 | Z8: =SUBSTITUTE(T8,".",",") -> 1,0123 | AA8: =SUBSTITUTE(U8,".",",") -> -9,2794 | AB8: =SUBSTITUTE(V8,".",",") -> 0,000 | AC8: 0 | AD8: 7.6 | AE8: 1.6 | AF8: =AB8-AD8 -> #VALUE! | AG8: =AC8-AE8 -> -1.6 | AI8: 0,03% | AJ8: 0,0004 | AL8: =Nodos!L7*1.1 -> 145.2 | AM8: =Nodos!L7*0.9 -> 118.8 | AN8: =Z8*'DATOS ESPERADOS'!K4 -> 1336236 | AQ8: 4 | AR8: 1.0123 | AS8: -9.2794 | AT8: =AR8*'DATOS ESPERADOS'!K4 -> 133.6236 | AU8: -9.2794 | AV8: 3 | AW8: 4 | AX8: =[1]Sheet1!$D$4 -> (-8.19544904231211+23.5308726290628j) | AZ8: 4 | BA8: 2 | BB8: 5 | BC8: 82.362 | BD8: 2.7816 | BE8: -79.41892 | BF8: 5.16873 | BG8: 0.856 | BH8: 2.46
B9: 5 | C9: PV | D9: 1.010 | E9: -14.149 | F9: 0.00 | G9: 35.66 | H9: 94.20 | I9: 19.00 | J9: =SUBSTITUTE(D9,".",",") -> 1,010 | K9: =SUBSTITUTE(E9,".",",") -> -14,149 | L9: =SUBSTITUTE(F9,".",",") -> 0,00 | M9: =SUBSTITUTE(G9,".",",") -> 35,66 | N9: =SUBSTITUTE(H9,".",",") -> 94,20 | O9: =SUBSTITUTE(I9,".",",") -> 19,00 | R9: 5 | S9: PV | T9: 1.0100 | U9: -14.1488 | V9: 0.000 | W9: 35.659 | X9: 94.200 | Y9: 19.000 | Z9: =SUBSTITUTE(T9,".",",") -> 1,0100 | AA9: =SUBSTITUTE(U9,".",",") -> -14,1488 | AB9: =SUBSTITUTE(V9,".",",") -> 0,000 | AC9: =SUBSTITUTE(W9,".",",") -> 35,659 | AD9: 94.2 | AE9: 19 | AF9: =AB9-AD9 -> #VALUE! | AG9: =AC9-AE9 -> 35640 | AI9: 0,00% | AJ9: -0,0002 | AL9: =Nodos!L8*1.1 -> 145.2 | AM9: =Nodos!L8*0.9 -> 118.8 | AN9: =Z9*'DATOS ESPERADOS'!K5 -> 1333200 | AQ9: 5 | AR9: 1.01 | AS9: -14.1488 | AT9: =AR9*'DATOS ESPERADOS'!K5 -> 133.32 | AU9: -14.1488 | AV9: 2 | AW9: 5 | AX9: =[1]Sheet1!$E$3 -> (-1.135960788173878+4.7724793282813565j) | AZ9: 5 | BA9: 2 | BB9: 6 | BC9: 60.38332 | BD9: 1.3865 | BE9: -58.43718 | BF9: 0.56699 | BG9: 2.943 | BH9: 12.36
B10: 6 | C10: PQ | D10: 1.011 | E10: -11.055 | F10: - | G10: - | H10: - | I10: - | J10: =SUBSTITUTE(D10,".",",") -> 1,011 | K10: =SUBSTITUTE(E10,".",",") -> -11,055 | L10: =SUBSTITUTE(F10,".",",") -> - | M10: =SUBSTITUTE(G10,".",",") -> - | N10: =SUBSTITUTE(H10,".",",") -> - | O10: =SUBSTITUTE(I10,".",",") -> - | R10: 6 | S10: PQ | T10: 1.0106 | U10: -11.0550 | V10: 0.000 | W10: --- | X10: 0.000 | Y10: 0.000 | Z10: =SUBSTITUTE(T10,".",",") -> 1,0106 | AA10: =SUBSTITUTE(U10,".",",") -> -11,0550 | AB10: =SUBSTITUTE(V10,".",",") -> 0,000 | AC10: 0 | AD10: 0 | AE10: 0 | AF10: =AB10-AD10 -> #VALUE! | AG10: =AC10-AE10 -> 0 | AI10: 0,04% | AJ10: 0 | AL10: =Nodos!L9*1.1 -> 145.2 | AM10: =Nodos!L9*0.9 -> 118.8 | AN10: =Z10*'DATOS ESPERADOS'!K6 -> 1333992 | AQ10: 6 | AR10: 1.0106 | AS10: -11.055 | AT10: =AR10*'DATOS ESPERADOS'!K6 -> 133.3992 | AU10: -11.055 | AV10: 2 | AW10: 6 | AX10: =[1]Sheet1!$F$3 -> (-1.6861448807654689+5.116477495334806j) | AZ10: 6 | BA10: 3 | BB10: 4 | BC10: 82.15958 | BD10: -3.79906 | BE10: -81.30373 | BF10: 5.38798 | BG10: 1.946 | BH10: 5.9
B11: 7 | C11: PQ | D11: 1.003 | E11: -12.852 | F11: - | G11: - | H11: 22.80 | I11: 10.90 | J11: =SUBSTITUTE(D11,".",",") -> 1,003 | K11: =SUBSTITUTE(E11,".",",") -> -12,852 | L11: =SUBSTITUTE(F11,".",",") -> - | M11: =SUBSTITUTE(G11,".",",") -> - | N11: =SUBSTITUTE(H11,".",",") -> 22,80 | O11: =SUBSTITUTE(I11,".",",") -> 10,90 | R11: 7 | S11: PQ | T11: 1.0026 | U11: -12.8523 | V11: 0.000 | W11: --- | X11: 22.800 | Y11: 10.900 | Z11: =SUBSTITUTE(T11,".",",") -> 1,0026 | AA11: =SUBSTITUTE(U11,".",",") -> -12,8523 | AB11: =SUBSTITUTE(V11,".",",") -> 0,000 | AC11: 0 | AD11: 22.8 | AE11: 10.9 | AF11: =AB11-AD11 -> #VALUE! | AG11: =AC11-AE11 -> -10.9 | AI11: 0,04% | AJ11: 0,0003 | AL11: =Nodos!L10*1.1 -> 145.2 | AM11: =Nodos!L10*0.9 -> 118.8 | AN11: =Z11*'DATOS ESPERADOS'!K7 -> 1323432 | AQ11: 7 | AR11: 1.0026 | AS11: -12.8523 | AT11: =AR11*'DATOS ESPERADOS'!K7 -> 132.3432 | AU11: -12.8523 | AV11: 4 | AW11: 6 | AX11: =[1]Sheet1!$F$5 -> (-6.413123730174556+22.31120356548123j) | AZ11: 7 | BA11: 4 | BB11: 6 | BC11: 72.14229 | BD11: -15.8544 | BE11: -71.51039 | BF11: 17.13202 | BG11: 0.632 | BH11: 2.2
B12: 8 | C12: PV | D12: 1.010 | E12: -11.797 | F12: 0.00 | G12: 36.11 | H12: 30.00 | I12: 30.00 | J12: =SUBSTITUTE(D12,".",",") -> 1,010 | K12: =SUBSTITUTE(E12,".",",") -> -11,797 | L12: =SUBSTITUTE(F12,".",",") -> 0,00 | M12: =SUBSTITUTE(G12,".",",") -> 36,11 | N12: =SUBSTITUTE(H12,".",",") -> 30,00 | O12: =SUBSTITUTE(I12,".",",") -> 30,00 | R12: 8 | S12: PV | T12: 1.0100 | U12: -11.7974 | V12: 0.000 | W12: 36.111 | X12: 30.000 | Y12: 30.000 | Z12: =SUBSTITUTE(T12,".",",") -> 1,0100 | AA12: =SUBSTITUTE(U12,".",",") -> -11,7974 | AB12: =SUBSTITUTE(V12,".",",") -> 0,000 | AC12: =SUBSTITUTE(W12,".",",") -> 36,111 | AD12: 30 | AE12: 30 | AF12: =AB12-AD12 -> #VALUE! | AG12: =AC12-AE12 -> 36081 | AI12: 0,00% | AJ12: 0,0004 | AL12: =Nodos!L11*1.1 -> 145.2 | AM12: =Nodos!L11*0.9 -> 118.8 | AN12: =Z12*'DATOS ESPERADOS'!K8 -> 1333200 | AQ12: 8 | AR12: 1.01 | AS12: -11.7974 | AT12: =AR12*'DATOS ESPERADOS'!K8 -> 133.32 | AU12: -11.7974 | AV12: 5 | AW12: 7 | AX12: =[1]Sheet1!$G$6 -> (-2.954020035961983+7.449267916773697j) | AZ12: 8 | BA12: 4 | BB12: 12 | BC12: 41.18673 | BD12: 13.44527 | BE12: -44.19177 | BF12: -9.73689 | BG12: 0.169 | BH12: 0.43
B13: 9 | C13: PQ | D13: 1.051 | E13: -14.098 | F13: - | G13: - | H13: - | I13: - | J13: =SUBSTITUTE(D13,".",",") -> 1,051 | K13: =SUBSTITUTE(E13,".",",") -> -14,098 | L13: =SUBSTITUTE(F13,".",",") -> - | M13: =SUBSTITUTE(G13,".",",") -> - | N13: =SUBSTITUTE(H13,".",",") -> - | O13: =SUBSTITUTE(I13,".",",") -> - | R13: 9 | S13: PQ | T13: 1.0511 | U13: -14.0980 | V13: 0.000 | W13: --- | X13: 0.000 | Y13: 0.000 | Z13: =SUBSTITUTE(T13,".",",") -> 1,0511 | AA13: =SUBSTITUTE(U13,".",",") -> -14,0980 | AB13: =SUBSTITUTE(V13,".",",") -> 0,000 | AC13: 0 | AD13: 0 | AE13: 0 | AF13: =AB13-AD13 -> #VALUE! | AG13: =AC13-AE13 -> 0 | AI13: 0,01% | AJ13: 0 | AL13: =Nodos!L12*1.1 -> 1.1 | AM13: =Nodos!L12*0.9 -> 0.9 | AN13: =Z13*'DATOS ESPERADOS'!K9 -> 10511 | AQ13: 9 | AR13: 1.0511 | AS13: -14.098 | AT13: =AR13*'DATOS ESPERADOS'!K9 -> 1.0511 | AU13: -14.098 | AV13: 6 | AW13: 7 | AX13: =[1]Sheet1!$G$7 -> (-3.590210423980992+11.02611441072814j) | AZ13: 9 | BA13: 5 | BB13: 7 | BC13: -14.78331 | BD13: 11.48843 | BE13: 14.95264 | BF13: -13.12722 | BG13: 0.381 | BH13: 1.17
B14: 10 | C14: PQ | D14: 1.045 | E14: -15.688 | F14: - | G14: - | H14: 5.80 | I14: 2.00 | J14: =SUBSTITUTE(D14,".",",") -> 1,045 | K14: =SUBSTITUTE(E14,".",",") -> -15,688 | L14: =SUBSTITUTE(F14,".",",") -> - | M14: =SUBSTITUTE(G14,".",",") -> - | N14: =SUBSTITUTE(H14,".",",") -> 5,80 | O14: =SUBSTITUTE(I14,".",",") -> 2,00 | R14: 10 | S14: PQ | T14: 1.0454 | U14: -15.6882 | V14: 0.000 | W14: --- | X14: 5.800 | Y14: 2.000 | Z14: =SUBSTITUTE(T14,".",",") -> 1,0454 | AA14: =SUBSTITUTE(U14,".",",") -> -15,6882 | AB14: =SUBSTITUTE(V14,".",",") -> 0,000 | AC14: 0 | AD14: 5.8 | AE14: 2 | AF14: =AB14-AD14 -> #VALUE! | AG14: =AC14-AE14 -> -2 | AI14: 0,04% | AJ14: 0,0002 | AL14: =Nodos!L13*1.1 -> 36.3 | AM14: =Nodos!L13*0.9 -> 29.7 | AN14: =Z14*'DATOS ESPERADOS'!K10 -> 344982 | AQ14: 10 | AR14: 1.0454 | AS14: -15.6882 | AT14: =AR14*'DATOS ESPERADOS'!K10 -> 34.4982 | AU14: -15.6882 | AV14: 6 | AW14: 8 | AX14: =[1]Sheet1!$H$7 -> (-6.289308176100628+22.0125786163522j) | AZ14: 10 | BA14: 6 | BB14: 7 | BC14: 38.12094 | BD14: -2.81326 | BE14: -37.74004 | BF14: 2.26052 | BG14: 0.108 | BH14: 0.38
B15: 11 | C15: PV | D15: 1.082 | E15: -14.098 | F15: 0.00 | G15: 16.06 | H15: - | I15: - | J15: =SUBSTITUTE(D15,".",",") -> 1,082 | K15: =SUBSTITUTE(E15,".",",") -> -14,098 | L15: =SUBSTITUTE(F15,".",",") -> 0,00 | M15: =SUBSTITUTE(G15,".",",") -> 16,06 | N15: =SUBSTITUTE(H15,".",",") -> - | O15: =SUBSTITUTE(I15,".",",") -> - | R15: 11 | S15: PV | T15: 1.0820 | U15: -14.0980 | V15: 0.000 | W15: 16.057 | X15: 0.000 | Y15: 0.000 | Z15: =SUBSTITUTE(T15,".",",") -> 1,0820 | AA15: =SUBSTITUTE(U15,".",",") -> -14,0980 | AB15: =SUBSTITUTE(V15,".",",") -> 0,000 | AC15: =SUBSTITUTE(W15,".",",") -> 16,057 | AD15: 0 | AE15: 0 | AF15: =AB15-AD15 -> #VALUE! | AG15: =AC15-AE15 -> 16057 | AI15: 0,00% | AJ15: 0 | AL15: =Nodos!L14*1.1 -> 12.1 | AM15: =Nodos!L14*0.9 -> 9.9 | AN15: =Z15*'DATOS ESPERADOS'!K11 -> 119020 | AQ15: 11 | AR15: 1.082 | AS15: -14.098 | AT15: =AR15*'DATOS ESPERADOS'!K11 -> 11.902 | AU15: -14.098 | AV15: 6 | AW15: 9 | AX15: =[1]Sheet1!$I$7 -> 4.915840805411357j | AZ15: 11 | BA15: 6 | BB15: 8 | BC15: 29.54743 | BD15: -7.25399 | BE15: -29.43943 | BF15: 6.71337 | BG15: 0 | BH15: 1.62
B16: 12 | C16: PQ | D16: 1.057 | E16: -14.933 | F16: - | G16: - | H16: 11.20 | I16: 7.50 | J16: =SUBSTITUTE(D16,".",",") -> 1,057 | K16: =SUBSTITUTE(E16,".",",") -> -14,933 | L16: =SUBSTITUTE(F16,".",",") -> - | M16: =SUBSTITUTE(G16,".",",") -> - | N16: =SUBSTITUTE(H16,".",",") -> 11,20 | O16: =SUBSTITUTE(I16,".",",") -> 7,50 | R16: 12 | S16: PQ | T16: 1.0573 | U16: -14.9329 | V16: 0.000 | W16: --- | X16: 11.200 | Y16: 7.500 | Z16: =SUBSTITUTE(T16,".",",") -> 1,0573 | AA16: =SUBSTITUTE(U16,".",",") -> -14,9329 | AB16: =SUBSTITUTE(V16,".",",") -> 0,000 | AC16: 0 | AD16: 11.2 | AE16: 7.5 | AF16: =AB16-AD16 -> #VALUE! | AG16: =AC16-AE16 -> -7.5 | AI16: 0,03% | AJ16: -0.0001 | AL16: =Nodos!L15*1.1 -> 36.3 | AM16: =Nodos!L15*0.9 -> 29.7 | AN16: =Z16*'DATOS ESPERADOS'!K12 -> 348909 | AQ16: 12 | AR16: 1.0573 | AS16: -14.9329 | AT16: =AR16*'DATOS ESPERADOS'!K12 -> 34.8909 | AU16: -14.9329 | AV16: 6 | AW16: 10 | AX16: =[1]Sheet1!$J$7 -> 1.8561002591115963j | AZ16: 12 | BA16: 6 | BB16: 9 | BC16: 27.11035 | BD16: -7.91212 | BE16: -27.72019 | BF16: 9.71443 | BG16: 0 | BH16: 1.28
B17: 13 | C17: PV | D17: 1.071 | E17: -14.933 | F17: 0.00 | G17: 10.45 | H17: - | I17: - | J17: =SUBSTITUTE(D17,".",",") -> 1,071 | K17: =SUBSTITUTE(E17,".",",") -> -14,933 | L17: =SUBSTITUTE(F17,".",",") -> 0,00 | M17: =SUBSTITUTE(G17,".",",") -> 10,45 | N17: =SUBSTITUTE(H17,".",",") -> - | O17: =SUBSTITUTE(I17,".",",") -> - | R17: 13 | S17: PV | T17: 1.0710 | U17: -14.9329 | V17: 0.000 | W17: 10.451 | X17: 0.000 | Y17: 0.000 | Z17: =SUBSTITUTE(T17,".",",") -> 1,0710 | AA17: =SUBSTITUTE(U17,".",",") -> -14,9329 | AB17: =SUBSTITUTE(V17,".",",") -> 0,000 | AC17: =SUBSTITUTE(W17,".",",") -> 10,451 | AD17: 0 | AE17: 0 | AF17: =AB17-AD17 -> #VALUE! | AG17: =AC17-AE17 -> 10451 | AI17: 0,00% | AJ17: -0.0001 | AL17: =Nodos!L16*1.1 -> 12.1 | AM17: =Nodos!L16*0.9 -> 9.9 | AN17: =Z17*'DATOS ESPERADOS'!K13 -> 117810 | AQ17: 13 | AR17: 1.071 | AS17: -14.9329 | AT17: =AR17*'DATOS ESPERADOS'!K13 -> 11.781 | AU17: -14.9329 | AV17: 9 | AW17: 11 | AX17: =[1]Sheet1!$K$10 -> 4.8076923076923075j | AZ17: 13 | BA17: 6 | BB17: 10 | BC17: 15.34871 | BD17: 0.17212 | BE17: -15.83975 | BF17: 1.10504 | BG17: 0 | BH17: 0.46
B18: 14 | C18: PQ | D18: 1.043 | E18: -15.825 | F18: - | G18: - | H18: 6.20 | I18: 1.60 | J18: =SUBSTITUTE(D18,".",",") -> 1,043 | K18: =SUBSTITUTE(E18,".",",") -> -15,825 | L18: =SUBSTITUTE(F18,".",",") -> - | M18: =SUBSTITUTE(G18,".",",") -> - | N18: =SUBSTITUTE(H18,".",",") -> 6,20 | O18: =SUBSTITUTE(I18,".",",") -> 1,60 | R18: 14 | S18: PQ | T18: 1.0425 | U18: -15.8245 | V18: 0.000 | W18: --- | X18: 6.200 | Y18: 1.600 | Z18: =SUBSTITUTE(T18,".",",") -> 1,0425 | AA18: =SUBSTITUTE(U18,".",",") -> -15,8245 | AB18: =SUBSTITUTE(V18,".",",") -> 0,000 | AC18: 0 | AD18: 6.2 | AE18: 1.6 | AF18: =AB18-AD18 -> #VALUE! | AG18: =AC18-AE18 -> -1.6 | AI18: 0,05% | AJ18: -0,0005 | AL18: =Nodos!L17*1.1 -> 36.3 | AM18: =Nodos!L17*0.9 -> 29.7 | AN18: =Z18*'DATOS ESPERADOS'!K14 -> 344025 | AQ18: 14 | AR18: 1.0425 | AS18: -15.8245 | AT18: =AR18*'DATOS ESPERADOS'!K14 -> 34.4025 | AU18: -15.8245 | AV18: 9 | AW18: 10 | AX18: =[1]Sheet1!$J$10 -> 9.090909090909092j | AZ18: 14 | BA18: 6 | BB18: 28 | BC18: 18.66285 | BD18: 0.0759 | BE18: -18.60512 | BF18: -1.19441 | BG18: 0 | BH18: 0.8
B19: 15 | C19: PQ | D19: 1.038 | E19: -15.916 | F19: - | G19: - | H19: 8.20 | I19: 2.50 | J19: =SUBSTITUTE(D19,".",",") -> 1,038 | K19: =SUBSTITUTE(E19,".",",") -> -15,916 | L19: =SUBSTITUTE(F19,".",",") -> - | M19: =SUBSTITUTE(G19,".",",") -> - | N19: =SUBSTITUTE(H19,".",",") -> 8,20 | O19: =SUBSTITUTE(I19,".",",") -> 2,50 | R19: 15 | S19: PQ | T19: 1.0379 | U19: -15.9164 | V19: 0.000 | W19: --- | X19: 8.200 | Y19: 2.500 | Z19: =SUBSTITUTE(T19,".",",") -> 1,0379 | AA19: =SUBSTITUTE(U19,".",",") -> -15,9164 | AB19: =SUBSTITUTE(V19,".",",") -> 0,000 | AC19: 0 | AD19: 8.2 | AE19: 2.5 | AF19: =AB19-AD19 -> #VALUE! | AG19: =AC19-AE19 -> -2.5 | AI19: 0,01% | AJ19: 0,0004 | AL19: =Nodos!L18*1.1 -> 36.3 | AM19: =Nodos!L18*0.9 -> 29.7 | AN19: =Z19*'DATOS ESPERADOS'!K15 -> 342507 | AQ19: 15 | AR19: 1.0379 | AS19: -15.9164 | AT19: =AR19*'DATOS ESPERADOS'!K15 -> 34.2507 | AU19: -15.9164 | AV19: 4 | AW19: 12 | AX19: =[1]Sheet1!$L$5 -> 4.1912553648068664j | AZ19: 15 | BA19: 8 | BB19: 28 | BC19: -0.5449 | BD19: -0.54412 | BE19: 0.54676 | BF19: -3.80354 | BG19: 0 | BH19: 4.69
B20: 16 | C20: PQ | D20: 1.045 | E20: -15.515 | F20: - | G20: - | H20: 3.50 | I20: 1.80 | J20: =SUBSTITUTE(D20,".",",") -> 1,045 | K20: =SUBSTITUTE(E20,".",",") -> -15,515 | L20: =SUBSTITUTE(F20,".",",") -> - | M20: =SUBSTITUTE(G20,".",",") -> - | N20: =SUBSTITUTE(H20,".",",") -> 3,50 | O20: =SUBSTITUTE(I20,".",",") -> 1,80 | R20: 16 | S20: PQ | T20: 1.0446 | U20: -15.5154 | V20: 0.000 | W20: --- | X20: 3.500 | Y20: 1.800 | Z20: =SUBSTITUTE(T20,".",",") -> 1,0446 | AA20: =SUBSTITUTE(U20,".",",") -> -15,5154 | AB20: =SUBSTITUTE(V20,".",",") -> 0,000 | AC20: 0 | AD20: 3.5 | AE20: 1.8 | AF20: =AB20-AD20 -> #VALUE! | AG20: =AC20-AE20 -> -1.8 | AI20: 0,04% | AJ20: 0,0004 | AL20: =Nodos!L19*1.1 -> 36.3 | AM20: =Nodos!L19*0.9 -> 29.7 | AN20: =Z20*'DATOS ESPERADOS'!K16 -> 344718 | AQ20: 16 | AR20: 1.0446 | AS20: -15.5154 | AT20: =AR20*'DATOS ESPERADOS'!K16 -> 34.4718 | AU20: -15.5154 | AV20: 12 | AW20: 13 | AX20: =[1]Sheet1!$M$13 -> 7.142857142857142j | AZ20: 16 | BA20: 9 | BB20: 10 | BC20: 27.72089 | BD20: 5.83132 | BE20: -27.72089 | BF20: -5.03236 | BG20: 0 | BH20: 0.13
B21: 17 | C21: PQ | D21: 1.040 | E21: -15.850 | F21: - | G21: - | H21: 9.00 | I21: 5.80 | J21: =SUBSTITUTE(D21,".",",") -> 1,040 | K21: =SUBSTITUTE(E21,".",",") -> -15,850 | L21: =SUBSTITUTE(F21,".",",") -> - | M21: =SUBSTITUTE(G21,".",",") -> - | N21: =SUBSTITUTE(H21,".",",") -> 9,00 | O21: =SUBSTITUTE(I21,".",",") -> 5,80 | R21: 17 | S21: PQ | T21: 1.0402 | U21: -15.8499 | V21: 0.000 | W21: --- | X21: 9.000 | Y21: 5.800 | Z21: =SUBSTITUTE(T21,".",",") -> 1,0402 | AA21: =SUBSTITUTE(U21,".",",") -> -15,8499 | AB21: =SUBSTITUTE(V21,".",",") -> 0,000 | AC21: 0 | AD21: 9 | AE21: 5.8 | AF21: =AB21-AD21 -> #VALUE! | AG21: =AC21-AE21 -> -5.8 | AI21: 0,02% | AJ21: -0.0001 | AL21: =Nodos!L20*1.1 -> 36.3 | AM21: =Nodos!L20*0.9 -> 29.7 | AN21: =Z21*'DATOS ESPERADOS'!K17 -> 343266 | AQ21: 17 | AR21: 1.0402 | AS21: -15.8499 | AT21: =AR21*'DATOS ESPERADOS'!K17 -> 34.3266 | AU21: -15.8499 | AV21: 12 | AW21: 14 | AX21: =[1]Sheet1!$N$13 -> (-1.5265676088395577+3.1734252729654173j) | AZ21: 17 | BA21: 9 | BB21: 11 | BC21: 0 | BD21: -15.6149 | BE21: 0 | BF21: 16.07394 | BG21: 0.074 | BH21: 0.15
B22: 18 | C22: PQ | D22: 1.028 | E22: -16.530 | F22: - | G22: - | H22: 3.20 | I22: 0.90 | J22: =SUBSTITUTE(D22,".",",") -> 1,028 | K22: =SUBSTITUTE(E22,".",",") -> -16,530 | L22: =SUBSTITUTE(F22,".",",") -> - | M22: =SUBSTITUTE(G22,".",",") -> - | N22: =SUBSTITUTE(H22,".",",") -> 3,20 | O22: =SUBSTITUTE(I22,".",",") -> 0,90 | R22: 18 | S22: PQ | T22: 1.0284 | U22: -16.5302 | V22: 0.000 | W22: --- | X22: 3.200 | Y22: 0.900 | Z22: =SUBSTITUTE(T22,".",",") -> 1,0284 | AA22: =SUBSTITUTE(U22,".",",") -> -16,5302 | AB22: =SUBSTITUTE(V22,".",",") -> 0,000 | AC22: 0 | AD22: 3.2 | AE22: 0.9 | AF22: =AB22-AD22 -> #VALUE! | AG22: =AC22-AE22 -> -0.9 | AI22: 0,04% | AJ22: 0,0002 | AL22: =Nodos!L21*1.1 -> 36.3 | AM22: =Nodos!L21*0.9 -> 29.7 | AN22: =Z22*'DATOS ESPERADOS'!K18 -> 339372 | AQ22: 18 | AR22: 1.0284 | AS22: -16.5302 | AT22: =AR22*'DATOS ESPERADOS'!K18 -> 33.9372 | AU22: -16.5302 | AV22: 12 | AW22: 15 | AX22: =[1]Sheet1!$O$13 -> (-3.0953961826564296+6.097275864326261j) | AZ22: 18 | BA22: 10 | BB22: 17 | BC22: 5.31859 | BD22: 4.39904 | BE22: -5.30447 | BF22: -4.3622 | BG22: 0.217 | BH22: 0.43
B23: 19 | C23: PQ | D23: 1.026 | E23: -16.704 | F23: - | G23: - | H23: 9.50 | I23: 3.40 | J23: =SUBSTITUTE(D23,".",",") -> 1,026 | K23: =SUBSTITUTE(E23,".",",") -> -16,704 | L23: =SUBSTITUTE(F23,".",",") -> - | M23: =SUBSTITUTE(G23,".",",") -> - | N23: =SUBSTITUTE(H23,".",",") -> 9,50 | O23: =SUBSTITUTE(I23,".",",") -> 3,40 | R23: 19 | S23: PQ | T23: 1.0259 | U23: -16.7037 | V23: 0.000 | W23: --- | X23: 9.500 | Y23: 3.400 | Z23: =SUBSTITUTE(T23,".",",") -> 1,0259 | AA23: =SUBSTITUTE(U23,".",",") -> -16,7037 | AB23: =SUBSTITUTE(V23,".",",") -> 0,000 | AC23: 0 | AD23: 9.5 | AE23: 3.4 | AF23: =AB23-AD23 -> #VALUE! | AG23: =AC23-AE23 -> -3.4 | AI23: 0,01% | AJ23: -0,0003 | AL23: =Nodos!L22*1.1 -> 36.3 | AM23: =Nodos!L22*0.9 -> 29.7 | AN23: =Z23*'DATOS ESPERADOS'!K19 -> 338547 | AQ23: 19 | AR23: 1.0259 | AS23: -16.7037 | AT23: =AR23*'DATOS ESPERADOS'!K19 -> 33.8547 | AU23: -16.7037 | AV23: 12 | AW23: 16 | AX23: =[1]Sheet1!$P$13 -> (-1.951997792280169+4.104359379111847j) | AZ23: 19 | BA23: 10 | BB23: 20 | BC23: 9.02692 | BD23: 3.7129 | BE23: -8.94532 | BF23: -3.53071 | BG23: 0.054 | BH23: 0.11
B24: 20 | C24: PQ | D24: 1.030 | E24: -16.507 | F24: - | G24: - | H24: 2.20 | I24: 0.70 | J24: =SUBSTITUTE(D24,".",",") -> 1,030 | K24: =SUBSTITUTE(E24,".",",") -> -16,507 | L24: =SUBSTITUTE(F24,".",",") -> - | M24: =SUBSTITUTE(G24,".",",") -> - | N24: =SUBSTITUTE(H24,".",",") -> 2,20 | O24: =SUBSTITUTE(I24,".",",") -> 0,70 | R24: 20 | S24: PQ | T24: 1.0300 | U24: -16.5072 | V24: 0.000 | W24: --- | X24: 2.200 | Y24: 0.700 | Z24: =SUBSTITUTE(T24,".",",") -> 1,0300 | AA24: =SUBSTITUTE(U24,".",",") -> -16,5072 | AB24: =SUBSTITUTE(V24,".",",") -> 0,000 | AC24: 0 | AD24: 2.2 | AE24: 0.7 | AF24: =AB24-AD24 -> #VALUE! | AG24: =AC24-AE24 -> -0.7 | AI24: 0,00% | AJ24: 0,0002 | AL24: =Nodos!L23*1.1 -> 36.3 | AM24: =Nodos!L23*0.9 -> 29.7 | AN24: =Z24*'DATOS ESPERADOS'!K20 -> 339900 | AQ24: 20 | AR24: 1.03 | AS24: -16.5072 | AT24: =AR24*'DATOS ESPERADOS'!K20 -> 33.99 | AU24: -16.5072 | AV24: 14 | AW24: 15 | AX24: =[1]Sheet1!$O$15 -> (-2.490952263999462+2.2508740593696492j) | AZ24: 20 | BA24: 10 | BB24: 21 | BC24: 15.78792 | BD24: 10.01464 | BE24: -15.67662 | BF24: -9.77508 | BG24: 0.006 | BH24: 0.01
B25: 21 | C25: PQ | D25: 1.033 | E25: -16.131 | F25: - | G25: - | H25: 17.50 | I25: 11.20 | J25: =SUBSTITUTE(D25,".",",") -> 1,033 | K25: =SUBSTITUTE(E25,".",",") -> -16,131 | L25: =SUBSTITUTE(F25,".",",") -> - | M25: =SUBSTITUTE(G25,".",",") -> - | N25: =SUBSTITUTE(H25,".",",") -> 17,50 | O25: =SUBSTITUTE(I25,".",",") -> 11,20 | R25: 21 | S25: PQ | T25: 1.0330 | U25: -16.1307 | V25: 0.000 | W25: --- | X25: 17.500 | Y25: 11.200 | Z25: =SUBSTITUTE(T25,".",",") -> 1,0330 | AA25: =SUBSTITUTE(U25,".",",") -> -16,1307 | AB25: =SUBSTITUTE(V25,".",",") -> 0,000 | AC25: 0 | AD25: 17.5 | AE25: 11.2 | AF25: =AB25-AD25 -> #VALUE! | AG25: =AC25-AE25 -> -11.2 | AI25: 0,00% | AJ25: -0,0003 | AL25: =Nodos!L24*1.1 -> 36.3 | AM25: =Nodos!L24*0.9 -> 29.7 | AN25: =Z25*'DATOS ESPERADOS'!K21 -> 340890 | AQ25: 21 | AR25: 1.033 | AS25: -16.1307 | AT25: =AR25*'DATOS ESPERADOS'!K21 -> 34.089 | AU25: -16.1307 | AV25: 16 | AW25: 17 | AX25: =[1]Sheet1!$Q$17 -> (-1.3190669363537615+4.8407742721532125j) | AZ25: 21 | BA25: 10 | BB25: 22 | BC25: 7.62723 | BD25: 4.62004 | BE25: -7.57433 | BF25: -4.51097 | BG25: 0.008 | BH25: 0.03
B26: 22 | C26: PQ | D26: 1.034 | E26: -16.116 | F26: - | G26: - | H26: - | I26: - | J26: =SUBSTITUTE(D26,".",",") -> 1,034 | K26: =SUBSTITUTE(E26,".",",") -> -16,116 | L26: =SUBSTITUTE(F26,".",",") -> - | M26: =SUBSTITUTE(G26,".",",") -> - | N26: =SUBSTITUTE(H26,".",",") -> - | O26: =SUBSTITUTE(I26,".",",") -> - | R26: 22 | S26: PQ | T26: 1.0335 | U26: -16.1164 | V26: 0.000 | W26: --- | X26: 0.000 | Y26: 0.000 | Z26: =SUBSTITUTE(T26,".",",") -> 1,0335 | AA26: =SUBSTITUTE(U26,".",",") -> -16,1164 | AB26: =SUBSTITUTE(V26,".",",") -> 0,000 | AC26: 0 | AD26: 0 | AE26: 0 | AF26: =AB26-AD26 -> #VALUE! | AG26: =AC26-AE26 -> 0 | AI26: 0,05% | AJ26: 0,0004 | AL26: =Nodos!L25*1.1 -> 36.3 | AM26: =Nodos!L25*0.9 -> 29.7 | AN26: =Z26*'DATOS ESPERADOS'!K22 -> 341055 | AQ26: 22 | AR26: 1.0335 | AS26: -16.1164 | AT26: =AR26*'DATOS ESPERADOS'!K22 -> 34.1055 | AU26: -16.1164 | AV26: 15 | AW26: 18 | AX26: =[1]Sheet1!$R$16 -> (-1.8108011504072024+3.6874189316306962j) | AZ26: 22 | BA26: 12 | BB26: 13 | BC26: 0 | BD26: -10.34644 | BE26: 0 | BF26: 10.4805 | BG26: 0.039 | BH26: 0.08
B27: 23 | C27: PQ | D27: 1.027 | E27: -16.307 | F27: - | G27: - | H27: 3.20 | I27: 1.60 | J27: =SUBSTITUTE(D27,".",",") -> 1,027 | K27: =SUBSTITUTE(E27,".",",") -> -16,307 | L27: =SUBSTITUTE(F27,".",",") -> - | M27: =SUBSTITUTE(G27,".",",") -> - | N27: =SUBSTITUTE(H27,".",",") -> 3,20 | O27: =SUBSTITUTE(I27,".",",") -> 1,60 | R27: 23 | S27: PQ | T27: 1.0274 | U27: -16.3066 | V27: 0.000 | W27: --- | X27: 3.200 | Y27: 1.600 | Z27: =SUBSTITUTE(T27,".",",") -> 1,0274 | AA27: =SUBSTITUTE(U27,".",",") -> -16,3066 | AB27: =SUBSTITUTE(V27,".",",") -> 0,000 | AC27: 0 | AD27: 3.2 | AE27: 1.6 | AF27: =AB27-AD27 -> #VALUE! | AG27: =AC27-AE27 -> -1.6 | AI27: 0,04% | AJ27: -0,0004 | AL27: =Nodos!L26*1.1 -> 36.3 | AM27: =Nodos!L26*0.9 -> 29.7 | AN27: =Z27*'DATOS ESPERADOS'!K23 -> 339042 | AQ27: 23 | AR27: 1.0274 | AS27: -16.3066 | AT27: =AR27*'DATOS ESPERADOS'!K23 -> 33.9042 | AU27: -16.3066 | AV27: 18 | AW27: 19 | AX27: =[1]Sheet1!$S$19 -> (-3.0756864340087167+6.218758799278971j) | AZ27: 23 | BA27: 12 | BB27: 14 | BC27: 7.85208 | BD27: 2.38983 | BE27: -7.7779 | BF27: -2.23562 | BG27: 0.005 | BH27: 0.01
B28: 24 | C28: PQ | D28: 1.022 | E28: -16.483 | F28: - | G28: - | H28: 8.70 | I28: 6.70 | J28: =SUBSTITUTE(D28,".",",") -> 1,022 | K28: =SUBSTITUTE(E28,".",",") -> -16,483 | L28: =SUBSTITUTE(F28,".",",") -> - | M28: =SUBSTITUTE(G28,".",",") -> - | N28: =SUBSTITUTE(H28,".",",") -> 8,70 | O28: =SUBSTITUTE(I28,".",",") -> 6,70 | R28: 24 | S28: PQ | T28: 1.0218 | U28: -16.4828 | V28: 0.000 | W28: --- | X28: 8.700 | Y28: 6.700 | Z28: =SUBSTITUTE(T28,".",",") -> 1,0218 | AA28: =SUBSTITUTE(U28,".",",") -> -16,4828 | AB28: =SUBSTITUTE(V28,".",",") -> 0,000 | AC28: 0 | AD28: 8.7 | AE28: 6.7 | AF28: =AB28-AD28 -> #VALUE! | AG28: =AC28-AE28 -> -6.7 | AI28: 0,02% | AJ28: -0,0002 | AL28: =Nodos!L27*1.1 -> 36.3 | AM28: =Nodos!L27*0.9 -> 29.7 | AN28: =Z28*'DATOS ESPERADOS'!K24 -> 337194 | AQ28: 24 | AR28: 1.0218 | AS28: -16.4828 | AT28: =AR28*'DATOS ESPERADOS'!K24 -> 33.7194 | AU28: -16.4828 | AV28: 19 | AW28: 20 | AX28: =[1]Sheet1!$T$20 -> (-5.88235294117647+11.76470588235294j) | AZ28: 24 | BA28: 12 | BB28: 15 | BC28: 17.88391 | BD28: 6.77464 | BE28: -17.66733 | BF28: -6.34802 | BG28: 0.017 | BH28: 0.03
B29: 25 | C29: PQ | D29: 1.018 | E29: -16.055 | F29: - | G29: - | H29: - | I29: - | J29: =SUBSTITUTE(D29,".",",") -> 1,018 | K29: =SUBSTITUTE(E29,".",",") -> -16,055 | L29: =SUBSTITUTE(F29,".",",") -> - | M29: =SUBSTITUTE(G29,".",",") -> - | N29: =SUBSTITUTE(H29,".",",") -> - | O29: =SUBSTITUTE(I29,".",",") -> - | R29: 25 | S29: PQ | T29: 1.0176 | U29: -16.0546 | V29: 0.000 | W29: --- | X29: 0.000 | Y29: 0.000 | Z29: =SUBSTITUTE(T29,".",",") -> 1,0176 | AA29: =SUBSTITUTE(U29,".",",") -> -16,0546 | AB29: =SUBSTITUTE(V29,".",",") -> 0,000 | AC29: 0 | AD29: 0 | AE29: 0 | AF29: =AB29-AD29 -> #VALUE! | AG29: =AC29-AE29 -> 0 | AI29: 0,04% | AJ29: -0,0004 | AL29: =Nodos!L28*1.1 -> 36.3 | AM29: =Nodos!L28*0.9 -> 29.7 | AN29: =Z29*'DATOS ESPERADOS'!K25 -> 335808 | AQ29: 25 | AR29: 1.0176 | AS29: -16.0546 | AT29: =AR29*'DATOS ESPERADOS'!K25 -> 33.5808 | AU29: -16.0546 | AV29: 10 | AW29: 20 | AX29: =[1]Sheet1!$T$11 -> (-1.7848303152666303+3.98535828943083j) | AZ29: 25 | BA29: 12 | BB29: 16 | BC29: 7.24073 | BD29: 3.34288 | BE29: -7.18696 | BF29: -3.22983 | BG29: 0.082 | BH29: 0.18
B30: 26 | C30: PQ | D30: 1.000 | E30: -16.474 | F30: - | G30: - | H30: 3.50 | I30: 2.30 | J30: =SUBSTITUTE(D30,".",",") -> 1,000 | K30: =SUBSTITUTE(E30,".",",") -> -16,474 | L30: =SUBSTITUTE(F30,".",",") -> - | M30: =SUBSTITUTE(G30,".",",") -> - | N30: =SUBSTITUTE(H30,".",",") -> 3,50 | O30: =SUBSTITUTE(I30,".",",") -> 2,30 | R30: 26 | S30: PQ | T30: 0.9999 | U30: -16.4740 | V30: 0.000 | W30: --- | X30: 3.500 | Y30: 2.300 | Z30: =SUBSTITUTE(T30,".",",") -> 0,9999 | AA30: =SUBSTITUTE(U30,".",",") -> -16,4740 | AB30: =SUBSTITUTE(V30,".",",") -> 0,000 | AC30: 0 | AD30: 3.5 | AE30: 2.3 | AF30: =AB30-AD30 -> #VALUE! | AG30: =AC30-AE30 -> -2.3 | AI30: 0,01% | AJ30: 0 | AL30: =Nodos!L29*1.1 -> 36.3 | AM30: =Nodos!L29*0.9 -> 29.7 | AN30: =Z30*'DATOS ESPERADOS'!K26 -> #VALUE! | AQ30: 26 | AR30: 0.9999 | AS30: -16.474 | AT30: =AR30*'DATOS ESPERADOS'!K26 -> 32.9967 | AU30: -16.474 | AV30: 10 | AW30: 17 | AX30: =[1]Sheet1!$Q$11 -> (-3.956039125715353+10.317447719844054j) | AZ30: 26 | BA30: 14 | BB30: 15 | BC30: 1.58552 | BD30: 0.64742 | BE30: -1.57956 | BF30: -0.64203 | BG30: 0.014 | BH30: 0.04
